Workbook

Sheet Kangatang

Sheet bang ho tro tien xe
A1: TRƯỜNG PTDTNT THCS-THPT TỈNH LÂM ĐỒNG
A2: QUY ĐỊNH
A3: Định mức hỗ trợ tiền xe về địa phương sau sáp nhập
A5: Xã, huyện cũ | B5: Xã, huyện mới | C5: Số tiền | D5: Ghi chú
A6: 1.Địa bàn huyện Lạc Dương cũ
A7: Đạ Sar, Lạc Dương | B7: Xã Lạc Dương | C7: 100000
A8: Đạ Chais, Lạc Dương
A9: Đạ Nhim, Lạc Dương
A10: Xã Lát, Lạc Dương | B10: Phường LangBiang | C10: 50000
A11: 2.Địa bàn huyện Đơn Dương cũ
A12: Ka Đô, Đơn Dương | B12: Xã Ka Đô | C12: 140000
A13: Lạc Lâm, Đơn Dương
A14: Đạ Ròn, Đơn Dương | B14: Xã Đơn Dương | C14: 110000
A15: Tu Tra, Đơn Dương
A16: Thạnh Mỹ, Đơn Dương
A17: Ka Đơn, Đơn Dương | B17: Xã Quảng Lập | C17: 140000
A18: Quảng Lập, Đơn Dương
A19: Pró(Quảng Lập), Đơn Dương
A20: Lạc Xuân, Đơn Dương | B20: Xã D'ran | C20: 150000
A21: D'ran, Đơn Dương
A22: 3. Địa bàn huyện Lâm Hà cũ
A23: Liên Hà, Lâm Hà | B23: Xã Tân Hà | C23: 170000
A24: Đan Phượng, Lâm Hà
A25: Hoài Đức, Lâm Hà
A26: Tân Hà, Lâm Hà
A27: Tân Thanh, Lâm Hà | B27: Xã Phúc Thọ | C27: 180000
A28: Phúc Thọ, Lâm Hà
A29: Phú Sơn, Lâm Hà | B29: Xã Phú Sơn | C29: 150000
A30: Đạ Đờn, Lâm Hà
A31: Nam Hà - Lâm Hà | B31: Xã Nam Hà | C31: 90000
A32: Phi Tô, Lâm Hà
A33: Đinh Văn, Lâm Hà | B33: Xã Đinh Văn | C33: 140000
A34: Tân Văn - Lâm Hà
A35: Bình Thạnh, Lâm Hà
A36: Nam Ban, Lâm Hà | B36: Xã Nam Ban | C36: 60000
A37: Đông Thanh, Lâm Hà
A38: Mê Linh, Lâm Hà
A39: Gia Lâm, Lâm Hà
A40: 4.Địa bàn huyện Đức Trọng cũ
A41: Liên Hiệp, Đức Trọng | B41: Xã Hiệp Thạnh | C41: 60000
...

Sheet Sheet2
A1: 7.Địa bàn khác
A2: Lộc Thắng, Bảo Lâm | C2: Xã Bảo Lâm 1 | D2: 450000 | E2: 126 | F2: =AVERAGE(E2:E4) -> 117.66667 | G2: =D2/F2 -> 3824.3626 | H2: =20000*F2*0.2 -> 470666.67
A3: Lộc Quảng, Bảo Lâm | E3: 121
A4: Lộc Ngãi, Bảo Lâm | E4: 106
A5: Lộc An, Bảo Lâm | C5: Xã Bảo Lâm 2 | D5: 410000 | E5: 98 | F5: =AVERAGE(E5:E7) -> 107 | G5: =D5/F5 -> 3831.7757 | H5: =20000*F5*0.2 -> 428000
A6: Lộc Đức, Bảo Lâm | E6: 110
A7: Tân Lạc, Bảo Lâm | B7: 240000 | E7: 113
A8: Lộc Thành, Bảo Lâm | C8: Xã Bảo Lâm 3 | D8: 480000 | E8: 119 | F8: =AVERAGE(E8:E9) -> 123.5 | G8: =D8/F8 -> 3886.6397 | H8: =20000*F8*0.2 -> 494000
A9: Lộc Nam, Bảo Lâm | E9: 128
A10: Lộc Phú, Bảo Lâm | C10: Xã Bảo Lâm 4 | D10: 520000 | E10: 138 | F10: =AVERAGE(E10:E12) -> 134.33333 | G10: =D10/F10 -> 3870.9677 | H10: =20000*F10*0.2 -> 537333.33
A11: Lộc Lâm, Bảo Lâm | E11: 135
A12: B'Lá, Bảo Lâm | E12: 130
A13: Lộc Bảo, Bảo Lâm | C13: Xã Bảo Lâm 5 | D13: 610000 | E13: 154 | F13: =AVERAGE(E13:E14) -> 157.5 | G13: =D13/F13 -> 3873.0159 | H13: =20000*F13*0.2 -> 630000
A14: Lộc Bắc, Bảo Lâm | E14: 161
A16: Quảng Thành - Gia Nghĩa - Đăk Nông cũ | B16: 240000

Sheet Sheet1
A1: Xã, huyện cũ | B1: mức chi cũ | C1: Xã, huyện mới | D1: Số tiền | E1: Số km | F1: Km trung bình | G1: số tiền đồng/km | H1: số tiền xăng 0,2 l/km
A2: 1.Địa bàn huyện Lạc Dương cũ
A3: Đạ Sar, Lạc Dương | B3: 120000 | C3: Xã Lạc Dương | D3: 100000 | E3: 19 | F3: =AVERAGE(E3:E5) -> 33 | G3: =D3/F3 -> 3030.303 | H3: =20000*F3*0.2 -> 132000
A4: Đạ Chais, Lạc Dương | B4: 160000 | E4: 48 | I4: =IF(AND(F3>=70,F3<90),60%*H3,IF(AND(F3>=50,F3<70),70%*H3,IF(AND(F3>=30,F3<50),H3*80%,50%*H3))) -> 105600
A5: Đạ Nhim, Lạc Dương | B5: 160000 | E5: 32
A6: Xã Lát, Lạc Dương | B6: 100000 | C6: Phường LangBiang | D6: 50000 | E6: 20 | F6: 20 | G6: =D6/F6 -> 2500 | H6: =20000*F6*0.2 -> 80000 | I6: =IF(F6<30,50%*H6,H6) -> 40000
A7: 2.Địa bàn huyện Đơn Dương cũ
A8: Ka Đô, Đơn Dương | B8: 200000 | C8: Xã Ka Đô | D8: 140000 | E8: 43 | F8: =ROUND(AVERAGE(E8:E9),0) -> 44 | G8: =D8/F8 -> 3181.8182 | H8: =20000*F8*0.2 -> 176000
A9: Lạc Lâm, Đơn Dương | E9: 45 | I9: =IF(AND(F8>=70,F8<90),60%*H8,IF(AND(F8>=50,F8<70),70%*H8,IF(AND(F8>=30,F8<50),H8*80%,50%*H8))) -> 140800
A10: Đạ Ròn, Đơn Dương | B10: 80000 | C10: Xã Đơn Dương | D10: 110000 | E10: 29 | F10: =ROUND(AVERAGE(E10:E12),0) -> 37 | G10: =D10/F10 -> 2972.973 | H10: =20000*F10*0.2 -> 148000
A11: Tu Tra, Đơn Dương | B11: 120000 | E11: 44 | I11: =IF(F10<30,50%*H10,IF(AND(F10>=30,F10<50),H10*80%)) -> 118400
A12: Thạnh Mỹ, Đơn Dương | E12: 39
A13: Ka Đơn, Đơn Dương | B13: 160000 | C13: Xã Quảng Lập | D13: 140000 | E13: 45 | F13: =ROUND(AVERAGE(E13:E15),0) -> 44 | G13: =D13/F13 -> 3181.8182 | H13: =20000*F13*0.2 -> 176000
A14: Quảng Lập, Đơn Dương | E14: 43 | I14: =IF(F13<30,50%*H13,IF(AND(F13>=30,F13<50),H13*80%)) -> 140800
A15: Pró(Quảng Lập), Đơn Dương | B15: 200000 | E15: 45
A16: Lạc Xuân, Đơn Dương | B16: 200000 | C16: Xã D'ran | D16: 150000 | E16: 51 | F16: =ROUND(AVERAGE(E16:E17),0) -> 53 | G16: =D16/F16 -> 2830.1887 | H16: =20000*F16*0.2 -> 212000
A17: D'ran, Đơn Dương | E17: 55 | I17: =IF(AND(F16>=70,F16<90),60%*H16,IF(AND(F16>=50,F16<70),70%*H16,IF(AND(F16>=30,F16<50),H16*80%,50%*H16))) -> 148400
A18: 3. Địa bàn huyện Lâm Hà cũ
A19: Liên Hà, Lâm Hà | B19: 200000 | C19: Xã Tân Hà | D19: 170000 | E19: 66 | F19: =AVERAGE(E19:E22) -> 62 | G19: =D19/F19 -> 2741.9355 | H19: =20000*F19*0.2 -> 248000
A20: Đan Phượng, Lâm Hà | B20: 200000 | E20: 62 | I20: =IF(AND(F19>=70,F19<90),60%*H19,IF(AND(F19>=50,F19<70),70%*H19,IF(AND(F19>=30,F19<50),H19*80%,50%*H19))) -> 173600
A21: Hoài Đức, Lâm Hà | E21: 65
A22: Tân Hà, Lâm Hà | E22: 55
A23: Tân Thanh, Lâm Hà | B23: 200000 | C23: Xã Phúc Thọ | D23: 180000 | E23: 70 | F23: =AVERAGE(E23:E24) -> 66.5 | G23: =D23/F23 -> 2706.7669 | H23: =20000*F23*0.2 -> 266000
A24: Phúc Thọ, Lâm Hà | B24: 160000 | E24: 63 | I24: =IF(AND(F23>=70,F23<90),60%*H23,IF(AND(F23>=50,F23<70),70%*H23,IF(AND(F23>=30,F23<50),H23*80%,50%*H23))) -> 186200
A25: Phú Sơn, Lâm Hà | C25: Xã Phú Sơn | D25: 150000 | E25: 60 | F25: =AVERAGE(E25:E26) -> 56.5 | G25: =D25/F25 -> 2654.8673 | H25: =20000*F25*0.2 -> 226000
A26: Đạ Đờn, Lâm Hà | B26: 120000 | E26: 53 | I26: =IF(AND(F25>=70,F25<90),60%*H25,IF(AND(F25>=50,F25<70),70%*H25,IF(AND(F25>=30,F25<50),H25*80%,50%*H25))) -> 158200
A27: Nam Hà - Lâm Hà | C27: Xã Nam Hà | D27: 90000 | E27: 30 | F27: =AVERAGE(E27:E28) -> 30.5 | G27: =D27/F27 -> 2950.8197 | H27: =20000*F27*0.2 -> 122000
A28: Phi Tô, Lâm Hà | B28: 160000 | E28: 31 | I28: =IF(AND(F27>=70,F27<90),60%*H27,IF(AND(F27>=50,F27<70),70%*H27,IF(AND(F27>=30,F27<50),H27*80%,50%*H27))) -> 97600
A29: Đinh Văn, Lâm Hà | B29: 100000 | C29: Xã Đinh Văn | D29: 140000 | E29: 45 | F29: =AVERAGE(E29:E31) -> 44 | G29: =D29/F29 -> 3181.8182 | H29: =20000*F29*0.2 -> 176000
A30: Tân Văn - Lâm Hà | B30: 200000 | E30: 48 | I30: =IF(AND(F29>=70,F29<90),60%*H29,IF(AND(F29>=50,F29<70),70%*H29,IF(AND(F29>=30,F29<50),H29*80%,50%*H29))) -> 140800
A31: Bình Thạnh, Lâm Hà | E31: 39
A32: Nam Ban, Lâm Hà | C32: Xã Nam Ban | D32: 60000 | E32: 32 | F32: =AVERAGE(E32:E35) -> 27 | G32: =D32/F32 -> 2222.2222 | H32: =20000*F32*0.2 -> 108000
A33: Đông Thanh, Lâm Hà | E33: 28 | I33: =IF(AND(F32>=70,F32<90),60%*H32,IF(AND(F32>=50,F32<70),70%*H32,IF(AND(F32>=30,F32<50),H32*80%,50%*H32))) -> 54000
A34: Mê Linh, Lâm Hà | E34: 20
A35: Gia Lâm, Lâm Hà | E35: 28
A36: 4.Địa bàn huyện Đức Trọng cũ
A37: Liên Hiệp, Đức Trọng | B37: 80000 | C37: Xã Hiệp Thạnh | D37: 60000 | E37: 29 | F37: =AVERAGE(E37:E39) -> 25.333333 | G37: =D37/F37 -> 2368.4211 | H37: =20000*F37*0.2 -> 101333.33
A38: Hiệp An, Đức Trọng | B38: 80000 | E38: 19 | I38: =IF(AND(F37>=70,F37<90),60%*H37,IF(AND(F37>=50,F37<70),70%*H37,IF(AND(F37>=30,F37<50),H37*80%,50%*H37))) -> 50666.667
A39: Hiệp Thạnh, Đức Trọng | E39: 28
A40: Liên Nghĩa, Đức Trọng | C40: Xã Đức Trọng | D40: 110000 | E40: 32 | F40: =AVERAGE(E40:E41) -> 36 | G40: =D40/F40 -> 3055.5556 | H40: =20000*F40*0.2 -> 144000
...

Sheet Sheet3
A2: Lang Biang | B2: 50000
A3: Bảo Thuận | B3: 180000
A4: Di Linh | B4: 200000
A5: D'ran | B5: 150000
A6: Đam Rông 1 | B6: 170000
A7: Đam Rông 2 | B7: 210000
A8: Đam Rông 3 | B8: 230000
A9: Đam Rông 4 | B9: 200000
A10: Đinh Trang Thượng | B10: 190000
A11: Đinh Văn | B11: 140000
A12: Đơn Dương | B12: 110000
A13: Đức Trọng | B13: 110000
... A30: Ninh Gia | B30: 150000

Sheet Sheet4
B3: Họ và tên | C3: Lớp học | D3: Xã/Phường
B4: Bon Niêng K' A Ngọc Bé | C4: 6A | D4: Xã Đam Rông 4 | E4: =IFERROR(INDEX(Sheet3!$A$2:$A$30,MATCH(TRUE,ISNUMBER(SEARCH(Sheet3!$A$2:$A$30,D4)),0)),"") | F4: =IFERROR(INDEX(Sheet3!$A$2:$A$30,MATCH(TRUE,ISNUMBER(SEARCH(Sheet3!$A$2:$A$30,Sheet4!D4)),0)),"")
B5: Phi Srônh Khánh Di | C5: 6A | D5: Phường Lang Biang - Đà Lạt | E5: =IFERROR(INDEX(Sheet3!$A$2:$A$30,MATCH(TRUE,ISNUMBER(SEARCH(Sheet3!$A$2:$A$30,D5)),0)),"")
B6: Lơ Mu Phong Đạt | C6: 6A | D6: Xã Lạc Dương | E6: =IFERROR(INDEX(Sheet3!$A$2:$A$30,MATCH(TRUE,ISNUMBER(SEARCH(Sheet3!$A$2:$A$30,D6)),0)),"")
B7: Đa Goút Ngọc Hân | C7: 6A | D7: Phường Cam Ly - Đà Lạt | E7: =IFERROR(INDEX(Sheet3!$A$2:$A$30,MATCH(TRUE,ISNUMBER(SEARCH(Sheet3!$A$2:$A$30,D7)),0)),"")
B8: Khổng Hữu Nhật Hưng | C8: 6A | D8: Xã Đam Rông 4 | E8: =IFERROR(INDEX(Sheet3!$A$2:$A$30,MATCH(TRUE,ISNUMBER(SEARCH(Sheet3!$A$2:$A$30,D8)),0)),"")
B9: Kră Jăn Inly | C9: 6A | D9: Phường Lang Biang - Đà Lạt | E9: =IFERROR(INDEX(Sheet3!$A$2:$A$30,MATCH(TRUE,ISNUMBER(SEARCH(Sheet3!$A$2:$A$30,D9)),0)),"")
B10: Kon Sơ Jack Ky | C10: 6A | D10: Xã Lạc Dương | E10: =IFERROR(INDEX(Sheet3!$A$2:$A$30,MATCH(TRUE,ISNUMBER(SEARCH(Sheet3!$A$2:$A$30,D10)),0)),"")
B11: Kơ Să Lê Bê La | C11: 6A | D11: Xã Lạc Dương | E11: =IFERROR(INDEX(Sheet3!$A$2:$A$30,MATCH(TRUE,ISNUMBER(SEARCH(Sheet3!$A$2:$A$30,D11)),0)),"")
B12: Kon Sa Mỹ Lệ | C12: 6A | D12: Xã Lạc Dương | E12: =IFERROR(INDEX(Sheet3!$A$2:$A$30,MATCH(TRUE,ISNUMBER(SEARCH(Sheet3!$A$2:$A$30,D12)),0)),"")
B13: Rơ Ông K' Lộc | C13: 6A | D13: Phường Lang Biang - Đà Lạt | E13: =IFERROR(INDEX(Sheet3!$A$2:$A$30,MATCH(TRUE,ISNUMBER(SEARCH(Sheet3!$A$2:$A$30,D13)),0)),"")
B14: Rơ Ông Kim Luôn | C14: 6A | D14: Xã Đam Rông 4 | E14: =IFERROR(INDEX(Sheet3!$A$2:$A$30,MATCH(TRUE,ISNUMBER(SEARCH(Sheet3!$A$2:$A$30,D14)),0)),"")
B15: Rơ Ông K' Mã | C15: 6A | D15: Xã Đam Rông 4 | E15: =IFERROR(INDEX(Sheet3!$A$2:$A$30,MATCH(TRUE,ISNUMBER(SEARCH(Sheet3!$A$2:$A$30,D15)),0)),"")
B16: Bon Dơng Ja Min | C16: 6A | D16: Xã Lạc Dương | E16: =IFERROR(INDEX(Sheet3!$A$2:$A$30,MATCH(TRUE,ISNUMBER(SEARCH(Sheet3!$A$2:$A$30,D16)),0)),"")
... B592: Mbon K' Bền | C592: 12C2 | D592: Xã Đam Rông 4 | E592: =IFERROR(INDEX(Sheet3!$A$2:$A$30,MATCH(TRUE,ISNUMBER(SEARCH(Sheet3!$A$2:$A$30,D592)),0)),"")
B593: Bơ Nah Ria Nai Chi | C593: 12C2 | E593: =IFERROR(INDEX(Sheet3!$A$2:$A$30,MATCH(TRUE,ISNUMBER(SEARCH(Sheet3!$A$2:$A$30,D593)),0)),"")
B594: Ka Bùi Thị Quỳnh Chi | C594: 12C2 | D594: Xã Đinh Trang Thượng | E594: =IFERROR(INDEX(Sheet3!$A$2:$A$30,MATCH(TRUE,ISNUMBER(SEARCH(Sheet3!$A$2:$A$30,D594)),0)),"")
B595: Ma La Chi | C595: 12C2 | D595: Xã Đơn Dương | E595: =IFERROR(INDEX(Sheet3!$A$2:$A$30,MATCH(TRUE,ISNUMBER(SEARCH(Sheet3!$A$2:$A$30,D595)),0)),"")
B596: Rơ Ông Ha Chương | C596: 12C2 | D596: Xã Đam Rông 4 | E596: =IFERROR(INDEX(Sheet3!$A$2:$A$30,MATCH(TRUE,ISNUMBER(SEARCH(Sheet3!$A$2:$A$30,D596)),0)),"")
B597: Cil Múp K' Điều | C597: 12C2 | D597: Xã Đam Rông 4 | E597: =IFERROR(INDEX(Sheet3!$A$2:$A$30,MATCH(TRUE,ISNUMBER(SEARCH(Sheet3!$A$2:$A$30,D597)),0)),"")
B598: Lơ Mu K' Get | C598: 12C2 | D598: Xã Phú Sơn Lâm Hà | E598: =IFERROR(INDEX(Sheet3!$A$2:$A$30,MATCH(TRUE,ISNUMBER(SEARCH(Sheet3!$A$2:$A$30,D598)),0)),"")
B599: Nah Ria Nai Hạnh | C599: 12C2 | D599: Xã Đơn Dương | E599: =IFERROR(INDEX(Sheet3!$A$2:$A$30,MATCH(TRUE,ISNUMBER(SEARCH(Sheet3!$A$2:$A$30,D599)),0)),"")
B600: Dơng Gur K' Hằng | C600: 12C2 | D600: Xã Đam Rông 4 | E600: =IFERROR(INDEX(Sheet3!$A$2:$A$30,MATCH(TRUE,ISNUMBER(SEARCH(Sheet3!$A$2:$A$30,D600)),0)),"")
B601: Lương Thị Hằng | C601: 12C2 | D601: Xã Phúc Thọ Lâm Hà | E601: =IFERROR(INDEX(Sheet3!$A$2:$A$30,MATCH(TRUE,ISNUMBER(SEARCH(Sheet3!$A$2:$A$30,D601)),0)),"")
B602: Nưng Sang Ka Hồng | C602: 12C2 | D602: Xã Ka Đô | E602: =IFERROR(INDEX(Sheet3!$A$2:$A$30,MATCH(TRUE,ISNUMBER(SEARCH(Sheet3!$A$2:$A$30,D602)),0)),"")
B603: Đơng Gur Biu- Ling | C603: 12C2 | D603: Xã Lạc Dương | E603: =IFERROR(INDEX(Sheet3!$A$2:$A$30,MATCH(TRUE,ISNUMBER(SEARCH(Sheet3!$A$2:$A$30,D603)),0)),"")
B604: Sohao Thuỳ Linh | C604: 12C2 | D604: Xã Ka Đô | E604: =IFERROR(INDEX(Sheet3!$A$2:$A$30,MATCH(TRUE,ISNUMBER(SEARCH(Sheet3!$A$2:$A$30,D604)),0)),"")
B605: Rơ Ông Thô Ma | C605: 12C2 | D605: Xã Đam Rông 4 | E605: =IFERROR(INDEX(Sheet3!$A$2:$A$30,MATCH(TRUE,ISNUMBER(SEARCH(Sheet3!$A$2:$A$30,D605)),0)),"")
... B612: Nưng Sang Phương | C612: 12C2 | D612: Xã D'Ran | E612: =IFERROR(INDEX(Sheet3!$A$2:$A$30,MATCH(TRUE,ISNUMBER(SEARCH(Sheet3!$A$2:$A$30,D612)),0)),"")
B613: Thang Nai Quỳnh | C613: 12C2 | E613: =IFERROR(INDEX(Sheet3!$A$2:$A$30,MATCH(TRUE,ISNUMBER(SEARCH(Sheet3!$A$2:$A$30,D613)),0)),"")
B614: Liêng Hót Na Sôn | C614: 12C2 | D614: Phường Lang Biang - Đà Lạt | E614: =IFERROR(INDEX(Sheet3!$A$2:$A$30,MATCH(TRUE,ISNUMBER(SEARCH(Sheet3!$A$2:$A$30,D614)),0)),"")
B615: Bơ Ju Quyết Tâm | C615: 12C2 | D615: Xã Đơn Dương | E615: =IFERROR(INDEX(Sheet3!$A$2:$A$30,MATCH(TRUE,ISNUMBER(SEARCH(Sheet3!$A$2:$A$30,D615)),0)),"")
B616: Ka Thu | C616: 12C2 | D616: Xã Sơn Điền | E616: =IFERROR(INDEX(Sheet3!$A$2:$A$30,MATCH(TRUE,ISNUMBER(SEARCH(Sheet3!$A$2:$A$30,D616)),0)),"")
B617: Long Dưng K' Thuệ | C617: 12C2 | D617: Xã Đam Rông 4 | E617: =IFERROR(INDEX(Sheet3!$A$2:$A$30,MATCH(TRUE,ISNUMBER(SEARCH(Sheet3!$A$2:$A$30,D617)),0)),"")
B618: Rơ Ông K' Thúy | C618: 12C2 | D618: Phường Lang Biang - Đà Lạt | E618: =IFERROR(INDEX(Sheet3!$A$2:$A$30,MATCH(TRUE,ISNUMBER(SEARCH(Sheet3!$A$2:$A$30,D618)),0)),"")
B619: Ka' Thụy | C619: 12C2 | D619: Xã Đinh Trang Thượng | E619: =IFERROR(INDEX(Sheet3!$A$2:$A$30,MATCH(TRUE,ISNUMBER(SEARCH(Sheet3!$A$2:$A$30,D619)),0)),"")
B620: Nai Ý | C620: 12C2 | D620: Xã Ka Đô | E620: =IFERROR(INDEX(Sheet3!$A$2:$A$30,MATCH(TRUE,ISNUMBER(SEARCH(Sheet3!$A$2:$A$30,D620)),0)),"")
B621: Nông Thị Kim Anh | C621: 12C3 | D621: Xã Phúc Thọ Lâm Hà | E621: =IFERROR(INDEX(Sheet3!$A$2:$A$30,MATCH(TRUE,ISNUMBER(SEARCH(Sheet3!$A$2:$A$30,D621)),0)),"")
B622: Ka Nguyễn Ngọc Ánh | C622: 12C3 | D622: Xã Đinh Trang Thượng | E622: =IFERROR(INDEX(Sheet3!$A$2:$A$30,MATCH(TRUE,ISNUMBER(SEARCH(Sheet3!$A$2:$A$30,D622)),0)),"")
B623: Ria Jong Brờn | C623: 12C3 | D623: Xã Đơn Dương | E623: =IFERROR(INDEX(Sheet3!$A$2:$A$30,MATCH(TRUE,ISNUMBER(SEARCH(Sheet3!$A$2:$A$30,D623)),0)),"")
...
