Workbook

Sheet Tài khoản, Tiền xe
J1: Tài khoản, Tiên xe
J2: Ngày
A3: =COUNTA(A6:A650) -> 645 | B3: =COUNTIF(B6:B630,"?") -> 0 | C3: =COUNTA(C6:C650) -> 645 | D3: =COUNTA(D6:D630) -> 0 | E3: =COUNTA(E6:E630) -> 62 | J3: Thứ
A4: STT | B4: KT lớp | E4: =COUNTA(F6:F650) -> 645 | F4: Lớp | G4: Mã học sinh | H4: Mã MOET | I4: Số định danh | J4: Họ và tên | K4: Số tài khoản | L4: Ngân hàng | N4: Địa chỉ (nơi ở) | Q4: Khoảng cách từ nhà đến trường | R4: Tên trạm xe buýt gần nhà | S4: Cách di chuyển từ trường về nhà và ngược lại:
B5: =COUNTA(B6:B650) -> 107 | E5: STT | N5: Địa chỉ (nơi ở) theo tên xã mới | O5: xã mới | P5: hỗ trợ tiền xe | Q5: Đơn vị tính: Km
A6: 1 | B6: =IF(C6<>F6,"?","") | C6: 6A | E6: 1 | F6: 6A | G6: 2005929926 | J6: Bon Niêng K' A Ngọc Bé
A7: 2 | B7: =IF(C7<>F7,"?","") | C7: 6A | E7: 2 | F7: 6A | G7: 2005987563 | J7: Phi Srônh Khánh Di
A8: 3 | B8: =IF(C8<>F8,"?","") | C8: 6A | E8: 3 | F8: 6A | G8: 2007861016 | J8: Lơ Mu Phong Đạt
A9: 4 | B9: =IF(C9<>F9,"?","") | C9: 6A | E9: 4 | F9: 6A | G9: 2007275982 | J9: Đa Goút Ngọc Hân
A10: 5 | B10: =IF(C10<>F10,"?","") | C10: 6A | E10: 5 | F10: 6A | G10: 2005932767 | J10: Khổng Hữu Nhật Hưng
A11: 6 | B11: =IF(C11<>F11,"?","") | C11: 6A | E11: 6 | F11: 6A | G11: 2005987564 | J11: Kră Jăn Inly
A12: 7 | B12: =IF(C12<>F12,"?","") | C12: 6A | E12: 7 | F12: 6A | G12: 2007861253 | J12: Kon Sơ Jack Ky
A13: 8 | B13: =IF(C13<>F13,"?","") | C13: 6A | E13: 8 | F13: 6A | G13: 2007282084 | J13: Kơ Să Lê Bê La
A14: 9 | B14: =IF(C14<>F14,"?","") | C14: 6A | E14: 9 | F14: 6A | G14: 2007771303 | J14: Kon Sa Mỹ Lệ
A15: 10 | B15: =IF(C15<>F15,"?","") | C15: 6A | E15: 10 | F15: 6A | G15: 2005987566 | J15: Rơ Ông K' Lộc
A16: 11 | B16: =IF(C16<>F16,"?","") | C16: 6A | E16: 11 | F16: 6A | G16: 2005929465 | J16: Rơ Ông Kim Luôn
A17: 12 | B17: =IF(C17<>F17,"?","") | C17: 6A | E17: 12 | F17: 6A | G17: 2005929092 | J17: Rơ Ông K' Mã
... A34: 28 | B34: =IF(C34<>F34,"?","") | C34: 6A | E34: 29 | F34: 6A | G34: 2007290534 | J34: Liêng Jrang Lệ Trinh
A35: 29 | B35: =IF(C35<>F35,"?","") | C35: 6B | E35: 1 | F35: 6B | G35: 2005925205 | J35: Trương Văn An | N35: Thôn 2, Đam Rông 4, Lâm Đồng
A36: 30 | B36: =IF(C36<>F36,"?","") | C36: 6B | E36: 2 | F36: 6B | G36: 2007291610 | J36: Kră Jăn Ngọc Ánh | Q36: 30km | R36: không có | S36: xe máy
A37: 31 | B37: =IF(C37<>F37,"?","") | C37: 6B | E37: 3 | F37: 6B | G37: 2005985972 | J37: Liêng Hót Dêbôra | Q37: 24km | R37: không có | S37: xe máy
A38: 32 | B38: =IF(C38<>F38,"?","") | C38: 6B | E38: 4 | F38: 6B | G38: 2005927229 | J38: Bon Niêng K' Gưm | Q38: 60km | R38: không có | S38: xe máy
A39: 33 | B39: =IF(C39<>F39,"?","") | C39: 6B | E39: 5 | F39: 6B | G39: 2006153308 | J39: Đà Cắt K' Na Hi | Q39: 27km | R39: không có | S39: xe máy
A40: 34 | B40: =IF(C40<>F40,"?","") | C40: 6B | E40: 6 | F40: 6B | G40: 2006027380 | J40: Chu Nhật Huy
A41: 35 | B41: =IF(C41<>F41,"?","") | C41: 6B | E41: 7 | F41: 6B | G41: 2009200496 | J41: Lơ Mu Julia | Q41: 15km | R41: không có | S41: xe máy
A42: 36 | B42: =IF(C42<>F42,"?","") | C42: 6B | E42: 8 | F42: 6B | G42: 2005930679 | J42: Cil Múp Ja Kốp | Q42: 60km | R42: không có | S42: xe máy
A43: 37 | B43: =IF(C43<>F43,"?","") | C43: 6B | E43: 9 | F43: 6B | G43: 2007291628 | J43: Lơ Mu Shay La
A44: 38 | B44: =IF(C44<>F44,"?","") | C44: 6B | E44: 10 | F44: 6B | G44: 2007780281 | J44: Sơ Ao Ha Su Len
A45: 39 | B45: =IF(C45<>F45,"?","") | C45: 6B | E45: 11 | F45: 6B | G45: 2007269044 | J45: Cil Múp Linđa | Q45: 18km | R45: không có | S45: xe máy
A46: 40 | B46: =IF(C46<>F46,"?","") | C46: 6B | E46: 12 | F46: 6B | G46: 2007260129 | J46: Rơ Ông K Lu-y
A47: 41 | B47: =IF(C47<>F47,"?","") | C47: 6B | E47: 13 | F47: 6B | G47: 2007269046 | J47: Cil Múp Kê Ly | Q47: 18km | R47: không có | S47: xe máy
A48: 42 | B48: =IF(C48<>F48,"?","") | C48: 6B | E48: 14 | F48: 6B | G48: 2007104103 | J48: Bonnơr Thảo Mi | Q48: 15km | R48: không có | S48: xe máy
A49: 43 | B49: =IF(C49<>F49,"?","") | C49: 6B | E49: 15 | F49: 6B | G49: 2007291640 | J49: Lơ Mu Na Ham My
A50: 44 | B50: =IF(C50<>F50,"?","") | C50: 6B | E50: 16 | F50: 6B | G50: 2007265923 | J50: Kon Sơ Ly Na | Q50: 57km | R50: không có | S50: xe máy
A51: 45 | B51: =IF(C51<>F51,"?","") | C51: 6B | E51: 17 | F51: 6B | G51: 2007861497 | J51: Sơ Ao Su Nét
A52: 46 | B52: =IF(C52<>F52,"?","") | C52: 6B | E52: 18 | F52: 6B | G52: 2006153301 | J52: Kơ Să Phương Nghi | Q52: 27km | R52: không có | S52: xe máy
A53: 47 | B53: =IF(C53<>F53,"?","") | C53: 6B | E53: 19 | F53: 6B | G53: 2005985964 | J53: Liêng Hót Khánh Ngọc | Q53: 24km | R53: không có | S53: xe máy
A54: 48 | B54: =IF(C54<>F54,"?","") | C54: 6B | E54: 20 | F54: 6B | G54: 2005926081 | J54: Ka Să Sa Nia | Q54: 15km | R54: không có | S54: xe máy
A55: 49 | B55: =IF(C55<>F55,"?","") | C55: 6B | E55: 21 | F55: 6B | G55: 2006028162 | J55: Rơ Ông E Rin | Q55: 50km | R55: không có | S55: xe máy
A56: 50 | B56: =IF(C56<>F56,"?","") | C56: 6B | E56: 22 | F56: 6B | G56: 2009200511 | J56: Da Gout Saphy | Q56: 12km | R56: không có | S56: xe máy
...

Sheet tienxe
A1: Xã, huyện mới | B1: Số tiền
A2: LangBiang | B2: 80000
A3: Bảo Thuận | B3: 290000
A4: Đam Rông 1 | B4: 290000
A5: Đam Rông 2 | B5: 410000
A6: Đam Rông 3 | B6: 440000
A7: Đam Rông 4 | B7: 380000
A8: Di Linh | B8: 320000
A9: Đinh Trang Thượng | B9: 370000
A10: Đinh Văn | B10: 170000
A11: Đơn Dương | B11: 140000
A12: D'ran | B12: 210000
A13: Đức Trọng | B13: 140000
... A30: Tân Hội | B30: 160000
B62: 220000

Sheet 00 Ds
H2: Tháng 11 / 2024 | I2: 1 | L2: 2 | O2: 3 | R2: 4 | U2: 5 | X2: 6 | AA2: 7 | AD2: 8 | AG2: 9 | AJ2: 10 | AM2: 11 | AP2: 12 | AS2: 13 | AV2: 14 | AY2: 15 | BB2: 16 | BE2: 17 | BH2: 18 | BK2: 19 | BN2: 20 | BQ2: 21 | BT2: 22 | BW2: 23 | BZ2: 24 | CC2: 25 | CF2: 26 | CI2: 27 | CL2: 28 | CO2: 29 | CR2: 30 | CU2: 31
I3: Sáu | L3: Bảy | O3: CN | R3: Hai | U3: Ba | X3: Tư | AA3: Năm | AD3: Sáu | AG3: Bảy | AJ3: CN | AM3: Hai | AP3: Ba | AS3: Tư | AV3: Năm | AY3: Sáu | BB3: Bảy | BE3: CN | BH3: Hai | BK3: Ba | BN3: Tư | BQ3: Năm | BT3: Sáu | BW3: Bảy | BZ3: CN | CC3: Hai | CF3: Ba | CI3: Tư | CL3: Năm | CO3: Sáu | CR3: Bảy | CU3: CN
A4: STT | C4: Mã học sinh | D4: Mã MOET | E4: Số định danh | F4: TT | G4: Lớp | H4: Họ và tên | I4: Sáng | J4: Trưa | K4: Chiều | L4: Sáng | M4: Trưa | N4: Chiều | O4: Sáng | P4: Trưa | Q4: Chiều | R4: Sáng | S4: Trưa | T4: Chiều | U4: Sáng | V4: Trưa | W4: Chiều | X4: Sáng | Y4: Trưa | Z4: Chiều | AA4: Sáng | AB4: Trưa | AC4: Chiều | AD4: Sáng | AE4: Trưa | AF4: Chiều | AG4: Sáng | AH4: Trưa | AI4: Chiều | AJ4: Sáng | AK4: Trưa | AL4: Chiều | AM4: Sáng | AN4: Trưa | AO4: Chiều | AP4: Sáng | AQ4: Trưa | AR4: Chiều | AS4: Sáng | AT4: Trưa | AU4: Chiều | AV4: Sáng | AW4: Trưa | AX4: Chiều | AY4: Sáng | AZ4: Trưa | BA4: Chiều | BB4: Sáng | BC4: Trưa | BD4: Chiều | BE4: Sáng | BF4: Trưa | BG4: Chiều | BH4: Sáng | BI4: Trưa | BJ4: Chiều | BK4: Sáng | BL4: Trưa | BM4: Chiều | BN4: Sáng | BO4: Trưa | BP4: Chiều | BQ4: Sáng | BR4: Trưa | BS4: Chiều | BT4: Sáng | BU4: Trưa | BV4: Chiều | BW4: Sáng | BX4: Trưa | BY4: Chiều | BZ4: Sáng | CA4: Trưa | CB4: Chiều | CC4: Sáng | CD4: Trưa | CE4: Chiều | CF4: Sáng | CG4: Trưa | CH4: Chiều | CI4: Sáng | CJ4: Trưa | CK4: Chiều | CL4: Sáng | CM4: Trưa | CN4: Chiều | CO4: Sáng | CP4: Trưa | CQ4: Chiều | CR4: Sáng | CS4: Trưa | CT4: Chiều | CU4: Sáng | CV4: Trưa | CW4: Chiều
A6: 1 | B6: 6A | C6: 2003011968 | D6: 6870987192 | E6: 68313006414 | F6: 1 | G6: 6A | H6: Kră Jẵn Da Lia A | K6: về nhà
A7: 2 | B7: 6A | C7: 2007266660 | D7: 6839557963 | E7: 68313001040 | F7: =IF(B7=B6,F6+1,1) -> 2 | G7: 6A | H7: Da Gout Lê An | L7: 1
A8: 3 | B8: 6A | C8: 2003016149 | D8: 6884337059 | E8: 68213001414 | F8: =IF(B8=B7,F7+1,1) -> 3 | G8: 6A | H8: Ntôl Bùi Thiên Ân
A9: 4 | B9: 6A | C9: 2003015070 | D9: 6884337061 | E9: 68313008361 | F9: =IF(B9=B8,F8+1,1) -> 4 | G9: 6A | H9: Kơ Să Catherine | L9: 2
A10: 5 | B10: 6A | C10: 2003007509 | D10: 6884337062 | E10: 68313005641 | F10: =IF(B10=B9,F9+1,1) -> 5 | G10: 6A | H10: Kon Sơ Minh Châu
A11: 6 | B11: 6A | C11: 2007266667 | D11: 6839561127 | E11: 68313008475 | F11: =IF(B11=B10,F10+1,1) -> 6 | G11: 6A | H11: Cil Múp La Dy | L11: về nhà
A12: 7 | B12: 6A | C12: 2003014813 | D12: 6857524934 | E12: 68213005595 | F12: =IF(B12=B11,F11+1,1) -> 7 | G12: 6A | H12: Kơ Să Hê Grin
A13: 8 | B13: 6A | C13: 2003016195 | D13: 6884337063 | E13: 68313008744 | F13: =IF(B13=B12,F12+1,1) -> 8 | G13: 6A | H13: Dơng Gur Si Kha
A14: 9 | B14: 6A | C14: 2003007491 | D14: 6878019274 | E14: 68213010984 | F14: =IF(B14=B13,F13+1,1) -> 9 | G14: 6A | H14: Kơ Să Nông Tiến Khoa
A15: 10 | B15: 6A | C15: 2003016199 | D15: 6884337064 | E15: 68313003847 | F15: =IF(B15=B14,F14+1,1) -> 10 | G15: 6A | H15: Kon Sa The Kô
A16: 11 | B16: 6A | C16: 2001227492 | D16: 6878153419 | E16: 68213005916 | F16: =IF(B16=B15,F15+1,1) -> 11 | G16: 6A | H16: Dơng Gur Ha Krơng
A17: 12 | B17: 6A | C17: 2007250577 | D17: 6844474140 | E17: 68313007622 | F17: =IF(B17=B16,F16+1,1) -> 12 | G17: 6A | H17: Klong Như Lan
A18: 13 | B18: 6A | C18: 2007266483 | D18: 6844474196 | E18: 68313008509 | F18: =IF(B18=B17,F17+1,1) -> 13 | G18: 6A | H18: Rơ Ông K' Le
A19: 14 | B19: 6A | C19: 2003011956 | D19: 6844806319 | E19: 68313001061 | F19: =IF(B19=B18,F18+1,1) -> 14 | G19: 6A | H19: Kră Jăn K' Linh
A20: 15 | B20: 6A | C20: 2006153766 | D20: 6884337065 | F20: =IF(B20=B19,F19+1,1) -> 15 | G20: 6A | H20: Klong K' Loan | L20: đi lễ
A21: 16 | B21: 6A | C21: 2003016119 | D21: 6884337066 | E21: 68213012066 | F21: =IF(B21=B20,F20+1,1) -> 16 | G21: 6A | H21: Rơ Ông Ha Luis
A22: 17 | B22: 6A | C22: 2003011884 | D22: 6848391598 | E22: 68313014239 | F22: =IF(B22=B21,F21+1,1) -> 17 | G22: 6A | H22: Kon Sơ K' Khên Ly
A23: 18 | B23: 6A | C23: 2003007482 | D23: 6802301416 | E23: 68213011901 | F23: =IF(B23=B22,F22+1,1) -> 18 | G23: 6A | H23: Cil Pam Khôi Nguyên
A24: 19 | B24: 6A | C24: 2006153788 | D24: 6858294710 | E24: 68313005805 | F24: =IF(B24=B23,F23+1,1) -> 19 | G24: 6A | H24: Pang Ting Trắng Thu Nguyệt
A25: 20 | B25: 6A | C25: 2009201989 | D25: 6804793994 | E25: 17213010875 | F25: =IF(B25=B24,F24+1,1) -> 20 | G25: 6A | H25: Bạch Pang Thiện Nhân
A26: 21 | B26: 6A | C26: 2007115913 | D26: 6840162672 | E26: 68213006387 | F26: =IF(B26=B25,F25+1,1) -> 21 | G26: 6A | H26: Cêl Môp Rơ Ông Nhuận
A27: 22 | B27: 6A | C27: 2006163697 | D27: 6884337068 | E27: 68313012294 | F27: =IF(B27=B26,F26+1,1) -> 22 | G27: 6A | H27: Rơ Ông Kỳ Phương
A28: 23 | B28: 6A | C28: 2006153773 | D28: 6884337069 | F28: =IF(B28=B27,F27+1,1) -> 23 | G28: 6A | H28: Cil The Ry
A29: 24 | B29: 6A | C29: 2003012385 | D29: 6870986428 | E29: 68213002414 | F29: =IF(B29=B28,F28+1,1) -> 24 | G29: 6A | H29: Kră Jãn Na Than
A30: 25 | B30: 6A | C30: 2003014839 | D30: 6841159824 | E30: 68313003461 | F30: =IF(B30=B29,F29+1,1) -> 25 | G30: 6A | H30: Bon Dơng Lê Thiên
A31: 26 | B31: 6A | C31: 2007266638 | D31: 6855815162 | E31: 68213006448 | F31: =IF(B31=B30,F30+1,1) -> 26 | G31: 6A | H31: Klong Đức Thuận
A32: 27 | B32: 6A | C32: 2003007504 | D32: 6878019283 | E32: 68313004149 | F32: =IF(B32=B31,F31+1,1) -> 27 | G32: 6A | H32: Kơ Să Nông Thị Trang
A33: 28 | B33: 6A | C33: 2003016166 | D33: 6884337070 | E33: 68313004880 | F33: =IF(B33=B32,F32+1,1) -> 28 | G33: 6A | H33: Cil Múp Huyền Trân
A34: 29 | B34: 6A | C34: 2003014922 | D34: 6841189638 | E34: 68313010734 | F34: =IF(B34=B33,F33+1,1) -> 29 | G34: 6A | H34: Cil Yũ K' Hải Yến
A35: 30 | B35: 6B | C35: 2007266665 | D35: 6884660085 | E35: 68313012356 | F35: =IF(B35=B34,F34+1,1) -> 1 | G35: 6B | H35: Kră Jañ Ra Chel
A36: 31 | B36: 6B | C36: 2003016118 | D36: 6884337184 | E36: 68313010493 | F36: =IF(B36=B35,F35+1,1) -> 2 | G36: 6B | H36: Cil Múp My Rin Da
A37: 32 | B37: 6B | C37: 2003016112 | D37: 6884337185 | E37: 68213008583 | F37: =IF(B37=B36,F36+1,1) -> 3 | G37: 6B | H37: Ntôl Ha Dân
A38: 33 | B38: 6B | C38: 2003012369 | D38: 6870987105 | E38: 68313005559 | F38: =IF(B38=B37,F37+1,1) -> 4 | G38: 6B | H38: Kră Jăn K' Linh Đan
A39: 34 | B39: 6B | C39: 2006164505 | D39: 6884337186 | E39: 68313007286 | F39: =IF(B39=B38,F38+1,1) -> 5 | G39: 6B | H39: K' Hi
A40: 35 | B40: 6B | C40: 2003015048 | D40: 6841422869 | E40: 68213003815 | F40: =IF(B40=B39,F39+1,1) -> 6 | G40: 6B | H40: Cao Kon Sơ Song Hỉ
A41: 36 | B41: 6B | C41: 2006153764 | D41: 6884337188 | F41: =IF(B41=B40,F40+1,1) -> 7 | G41: 6B | H41: Liêng Hót Jêrôham
A42: 37 | B42: 6B | C42: 2003015002 | D42: 6841201362 | E42: 68313008094 | F42: =IF(B42=B41,F41+1,1) -> 8 | G42: 6B | H42: Lơ Mu Re Joice
...

Sheet DS Th 11
I1: Tháng 11 / 2024
I2: Ngày | J2: 1 | M2: 2 | P2: 3 | S2: 4 | V2: 5 | Y2: 6 | AB2: 7 | AE2: 8 | AH2: 9 | AK2: 10 | AN2: 11 | AQ2: 12 | AT2: 13 | AW2: 14 | AZ2: 15 | BC2: 16 | BF2: 17 | BI2: 18 | BL2: 19 | BO2: 20 | BR2: 21 | BU2: 22 | BX2: 23 | CA2: 24 | CD2: 25 | CG2: 26 | CJ2: 27 | CM2: 28 | CP2: 29 | CS2: 30 | CT2: 30 | CU2: 30 | CV2: 31 | CW2: 31 | CX2: 31
E3: =COUNTA(E6:E645) -> 640 | I3: Thứ | J3: Sáu | M3: Bảy | P3: CN | S3: Hai | V3: Ba | Y3: Tư | AB3: Năm | AE3: Sáu | AH3: Bảy | AK3: CN | AN3: Hai | AQ3: Ba | AT3: Tư | AW3: Năm | AZ3: Sáu | BC3: Bảy | BF3: CN | BI3: Hai | BL3: Ba | BO3: Tư | BR3: Năm | BU3: Sáu | BX3: Bảy | CA3: CN | CD3: Hai | CG3: Ba | CJ3: Tư | CM3: Năm | CP3: Sáu | CS3: Bảy | CT3: Bảy | CU3: Bảy | CV3: CN | CW3: CN | CX3: CN
A4: STT | E4: Lớp | F4: Mã học sinh | G4: Mã MOET | H4: Số định danh | I4: Họ và tên | J4: Sáng | K4: Trưa | L4: Chiều | M4: Sáng | N4: Trưa | O4: Chiều | P4: Sáng | Q4: Trưa | R4: Chiều | S4: Sáng | T4: Trưa | U4: Chiều | V4: Sáng | W4: Trưa | X4: Chiều | Y4: Sáng | Z4: Trưa | AA4: Chiều | AB4: Sáng | AC4: Trưa | AD4: Chiều | AE4: Sáng | AF4: Trưa | AG4: Chiều | AH4: Sáng | AI4: Trưa | AJ4: Chiều | AK4: Sáng | AL4: Trưa | AM4: Chiều | AN4: Sáng | AO4: Trưa | AP4: Chiều | AQ4: Sáng | AR4: Trưa | AS4: Chiều | AT4: Sáng | AU4: Trưa | AV4: Chiều | AW4: Sáng | AX4: Trưa | AY4: Chiều | AZ4: Sáng | BA4: Trưa | BB4: Chiều | BC4: Sáng | BD4: Trưa | BE4: Chiều | BF4: Sáng | BG4: Trưa | BH4: Chiều | BI4: Sáng | BJ4: Trưa | BK4: Chiều | BL4: Sáng | BM4: Trưa | BN4: Chiều | BO4: Sáng | BP4: Trưa | BQ4: Chiều | BR4: Sáng | BS4: Trưa | BT4: Chiều | BU4: Sáng | BV4: Trưa | BW4: Chiều | BX4: Sáng | BY4: Trưa | BZ4: Chiều | CA4: Sáng | CB4: Trưa | CC4: Chiều | CD4: Sáng | CE4: Trưa | CF4: Chiều | CG4: Sáng | CH4: Trưa | CI4: Chiều | CJ4: Sáng | CK4: Trưa | CL4: Chiều | CM4: Sáng | CN4: Trưa | CO4: Chiều | CP4: Sáng | CQ4: Trưa | CR4: Chiều | CS4: Sáng | CT4: Trưa | CU4: Chiều | CV4: Sáng | CW4: Trưa | CX4: Chiều
D5: STT
A6: 1 | B6: 6A | C6: =IF(B6=B5,C5+1,1) -> 1 | D6: 1 | E6: 6A | F6: 2003011968 | G6: 6870987192 | H6: 68313006414 | I6: Kră Jẵn Da Lia A
A7: 2 | B7: 6A | C7: =IF(B7=B6,C6+1,1) -> 2 | D7: 2 | E7: 6A | F7: 2007266660 | G7: 6839557963 | H7: 68313001040 | I7: Da Gout Lê An
A8: 3 | B8: 6A | C8: =IF(B8=B7,C7+1,1) -> 3 | D8: 3 | E8: 6A | F8: 2003016149 | G8: 6884337059 | H8: 68213001414 | I8: Ntôl Bùi Thiên Ân
A9: 4 | B9: 6A | C9: =IF(B9=B8,C8+1,1) -> 4 | D9: 4 | E9: 6A | F9: 2003015070 | G9: 6884337061 | H9: 68313008361 | I9: Kơ Să Catherine
A10: 5 | B10: 6A | C10: =IF(B10=B9,C9+1,1) -> 5 | D10: 5 | E10: 6A | F10: 2003007509 | G10: 6884337062 | H10: 68313005641 | I10: Kon Sơ Minh Châu
A11: 6 | B11: 6A | C11: =IF(B11=B10,C10+1,1) -> 6 | D11: 6 | E11: 6A | F11: 2007266667 | G11: 6839561127 | H11: 68313008475 | I11: Cil Múp La Dy
A12: 7 | B12: 6A | C12: =IF(B12=B11,C11+1,1) -> 7 | D12: 7 | E12: 6A | F12: 2003014813 | G12: 6857524934 | H12: 68213005595 | I12: Kơ Să Hê Grin
A13: 8 | B13: 6A | C13: =IF(B13=B12,C12+1,1) -> 8 | D13: 8 | E13: 6A | F13: 2003016195 | G13: 6884337063 | H13: 68313008744 | I13: Dơng Gur Si Kha | K13: Về nhà
A14: 9 | B14: 6A | C14: =IF(B14=B13,C13+1,1) -> 9 | D14: 9 | E14: 6A | F14: 2003007491 | G14: 6878019274 | H14: 68213010984 | I14: Kơ Să Nông Tiến Khoa
A15: 10 | B15: 6A | C15: =IF(B15=B14,C14+1,1) -> 10 | D15: 10 | E15: 6A | F15: 2003016199 | G15: 6884337064 | H15: 68313003847 | I15: Kon Sa The Kô
A16: 11 | B16: 6A | C16: =IF(B16=B15,C15+1,1) -> 11 | D16: 11 | E16: 6A | F16: 2001227492 | G16: 6878153419 | H16: 68213005916 | I16: Dơng Gur Ha Krơng
A17: 12 | B17: 6A | C17: =IF(B17=B16,C16+1,1) -> 12 | D17: 12 | E17: 6A | F17: 2007250577 | G17: 6844474140 | H17: 68313007622 | I17: Klong Như Lan
A18: 13 | B18: 6A | C18: =IF(B18=B17,C17+1,1) -> 13 | D18: 13 | E18: 6A | F18: 2007266483 | G18: 6844474196 | H18: 68313008509 | I18: Rơ Ông K' Le
A19: 14 | B19: 6A | C19: =IF(B19=B18,C18+1,1) -> 14 | D19: 14 | E19: 6A | F19: 2003011956 | G19: 6844806319 | H19: 68313001061 | I19: Kră Jăn K' Linh
A20: 15 | B20: 6A | C20: =IF(B20=B19,C19+1,1) -> 15 | D20: 15 | E20: 6A | F20: 2006153766 | G20: 6884337065 | H20: 68313008703 | I20: Klong K' Loan
A21: 16 | B21: 6A | C21: =IF(B21=B20,C20+1,1) -> 16 | D21: 16 | E21: 6A | F21: 2003016119 | G21: 6884337066 | H21: 68213012066 | I21: Rơ Ông Ha Luis
A22: 17 | B22: 6A | C22: =IF(B22=B21,C21+1,1) -> 17 | D22: 17 | E22: 6A | F22: 2003011884 | G22: 6848391598 | H22: 68313014239 | I22: Kon Sơ K' Khên Ly
A23: 18 | B23: 6A | C23: =IF(B23=B22,C22+1,1) -> 18 | D23: 18 | E23: 6A | F23: 2003007482 | G23: 6802301416 | H23: 68213011901 | I23: Cil Pam Khôi Nguyên
A24: 19 | B24: 6A | C24: =IF(B24=B23,C23+1,1) -> 19 | D24: 19 | E24: 6A | F24: 2006153788 | G24: 6858294710 | H24: 68313005805 | I24: Pang Ting Trắng Thu Nguyệt
A25: 20 | B25: 6A | C25: =IF(B25=B24,C24+1,1) -> 20 | D25: 20 | E25: 6A | F25: 2009201989 | G25: 6804793994 | H25: 17213010875 | I25: Bạch Pang Thiện Nhân
... A68: 63 | B68: 7A | C68: =IF(B68=B67,C67+1,1) -> 5 | D68: 5 | E68: 7A | F68: 2305220417 | G68: 6870987392 | H68: 68312010247 | I68: Lơ Mu Hanna
A69: 64 | B69: 7A | C69: =IF(B69=B68,C68+1,1) -> 6 | D69: 6 | E69: 7A | F69: 2305235648 | G69: 6880981629 | I69: Bon Niêng K' Hảo
A70: 65 | B70: 7A | C70: =IF(B70=B69,C69+1,1) -> 7 | D70: 7 | E70: 7A | F70: 2305229049 | G70: 6882528538 | H70: 68312001207 | I70: Kơ Să Mỹ Hiền
A71: 66 | B71: 7A | C71: =IF(B71=B70,C70+1,1) -> 8 | D71: 8 | E71: 7A | F71: 2305235841 | G71: 6880981631 | H71: 68312010088 | I71: Kơ Să Ly Su In
A72: 67 | B72: 7A | C72: =IF(B72=B71,C71+1,1) -> 9 | D72: 9 | E72: 7A | F72: 2305236349 | G72: 6880981632 | H72: 68312008245 | I72: Rơ Ông Siu Ly
A73: 68 | B73: 7A | C73: =IF(B73=B72,C72+1,1) -> 10 | D73: 10 | E73: 7A | F73: 2305240330 | G73: 6880981633 | H73: 68312014695 | I73: Kon Sa Na Ô Mi
A74: 69 | B74: 7A | C74: =IF(B74=B73,C73+1,1) -> 11 | D74: 11 | E74: 7A | F74: 2305230258 | G74: 6880981634 | H74: 68212009059 | I74: Cil Pam Thiết Nghiêm
A75: 70 | B75: 7A | C75: =IF(B75=B74,C74+1,1) -> 12 | D75: 12 | E75: 7A | F75: 2305218180 | G75: 6880981635 | H75: 68312004022 | I75: Klong Kim Ngọc
A76: 71 | B76: 7A | C76: =IF(B76=B75,C75+1,1) -> 13 | D76: 13 | E76: 7A | F76: 2305240119 | G76: 6880981637 | H76: 68312005102 | I76: Pang Ting Nguyễn Bảo Ngọc
A77: 72 | B77: 7A | C77: =IF(B77=B76,C76+1,1) -> 14 | D77: 14 | E77: 7A | F77: 2305219012 | G77: 6881032826 | H77: 68212003199 | I77: Da Căt Huy Nhật
A78: 73 | B78: 7A | C78: =IF(B78=B77,C77+1,1) -> 15 | D78: 15 | E78: 7A | F78: 2305231757 | G78: 6820650683 | H78: 68312009326 | I78: Lơ Mu Siu Niệm
A79: 74 | B79: 7A | C79: =IF(B79=B78,C78+1,1) -> 16 | D79: 16 | E79: 7A | F79: 2305212358 | G79: 6881032827 | H79: 68312003415 | I79: Păng Ting K' Builly Pốt
A80: 75 | B80: 7A | C80: =IF(B80=B79,C79+1,1) -> 17 | D80: 17 | E80: 7A | F80: 2305210128 | G80: 6821779141 | H80: 68312010567 | I80: Kră Jăn Ju Rin
A81: 76 | B81: 7A | C81: =IF(B81=B80,C80+1,1) -> 18 | D81: 18 | E81: 7A | F81: 2305216846 | G81: 6880981638 | H81: 68212010095 | I81: Kơ Să K' Thao
... A248: 243 | B248: 10B | C248: =IF(B248=B247,C247+1,1) -> 10 | D248: 10 | E248: 10B | F248: 2004948575 | G248: 6858719657 | H248: 68309003153 | I248: Cil Múp An Kỳ
...

Sheet 2526-DS HS không ăn old
E2: Tháng 10 / 2026 | J2: Ngày | K2: 1 | L2: 1 | M2: 1 | N2: 2 | O2: 2 | P2: 2 | Q2: 3 | R2: 3 | S2: 3 | T2: 4 | U2: 4 | V2: 4 | W2: 5 | X2: 5 | Y2: 5 | Z2: 6 | AA2: 6 | AB2: 6 | AC2: 7 | AD2: 7 | AE2: 7 | AF2: 8 | AG2: 8 | AH2: 8 | AI2: 9 | AJ2: 9 | AK2: 9 | AL2: 10 | AM2: 10 | AN2: 10 | AO2: 11 | AP2: 11 | AQ2: 11 | AR2: 12 | AS2: 12 | AT2: 12 | AU2: 13 | AV2: 13 | AW2: 13 | AX2: 14 | AY2: 14 | AZ2: 14 | BA2: 15 | BB2: 15 | BC2: 15 | BD2: 16 | BE2: 16 | BF2: 16 | BG2: 17 | BH2: 17 | BI2: 17 | BJ2: 18 | BK2: 18 | BL2: 18 | BM2: 19 | BN2: 19 | BO2: 19 | BP2: 20 | BS2: 21 | BT2: 21 | BU2: 21 | BV2: 22 | BW2: 22 | BX2: 22 | BY2: 23 | BZ2: 23 | CA2: 23 | CB2: 24 | CC2: 24 | CD2: 24 | CE2: 25 | CF2: 25 | CG2: 25 | CH2: 26 | CK2: 27 | CN2: 28 | CO2: 28 | CP2: 28 | CQ2: 29 | CR2: 29 | CS2: 29 | CT2: 30 | CU2: 30 | CV2: 30 | CW2: 31 | CX2: 31 | CY2: 31
A3: =COUNTA(A6:A650) -> 645 | B3: =COUNTIF(B6:B630,"?") -> 0 | C3: =COUNTA(C6:C650) -> 645 | D3: =COUNTA(D6:D630) -> 0 | E3: =COUNTA(E6:E630) -> 93 | F3: =COUNTA(F6:F650) -> 645 | J3: Thứ | K3: Tư | N3: Năm | Q3: Sáu | T3: Bảy | U3: Bảy | V3: Bảy | W3: CN | X3: CN | Y3: CN | Z3: Hai | AC3: Ba | AF3: Tư | AI3: Năm | AL3: Sáu | AM3: Sáu | AN3: Sáu | AO3: Bảy | AP3: Bảy | AQ3: Bảy | AR3: CN | AS3: CN | AT3: CN | AU3: Hai | AX3: Ba | BA3: Tư | BD3: Năm | BG3: Sáu | BJ3: Bảy | BK3: Bảy | BL3: Bảy | BM3: CN | BN3: CN | BO3: CN | BP3: Hai | BS3: Ba | BV3: Tư | BY3: Năm | CB3: Sáu | CE3: Bảy | CF3: Bảy | CG3: Bảy | CH3: CN | CI3: CN | CJ3: CN | CK3: Hai | CL3: Hai | CM3: Hai | CN3: Ba | CQ3: Tư | CT3: Năm | CW3: Sáu | CZ3: Bảy | DA3: Bảy | DB3: Bảy | DC3: CN | DD3: CN | DE3: CN | DF3: Bảy | DG3: Bảy | DH3: Bảy | DI3: CN | DJ3: CN | DK3: CN
A4: STT | B4: KT lớp | F4: Lớp | G4: Mã học sinh | H4: Mã MOET | I4: Số định danh | J4: Họ và tên | K4: Sáng | L4: Trưa | M4: Chiều | N4: Sáng | O4: Trưa | P4: Chiều | Q4: Sáng | R4: Trưa | S4: Chiều | T4: Sáng | U4: Trưa | V4: Chiều | W4: Sáng | X4: Trưa | Y4: Chiều | Z4: Sáng | AA4: Trưa | AB4: Chiều | AC4: Sáng | AD4: Trưa | AE4: Chiều | AF4: Sáng | AG4: Trưa | AH4: Chiều | AI4: Sáng | AJ4: Trưa | AK4: Chiều | AL4: Sáng | AM4: Trưa | AN4: Chiều | AO4: Sáng | AP4: Trưa | AQ4: Chiều | AR4: Sáng | AS4: Trưa | AT4: Chiều | AU4: Sáng | AV4: Trưa | AW4: Chiều | AX4: Sáng | AY4: Trưa | AZ4: Chiều | BA4: Sáng | BB4: Trưa | BC4: Chiều | BD4: Sáng | BE4: Trưa | BF4: Chiều | BG4: Sáng | BH4: Trưa | BI4: Chiều | BJ4: Sáng | BK4: Trưa | BL4: Chiều | BM4: Sáng | BN4: Trưa | BO4: Chiều | BP4: Sáng | BQ4: Trưa | BR4: Chiều | BS4: Sáng | BT4: Trưa | BU4: Chiều | BV4: Sáng | BW4: Trưa | BX4: Chiều | BY4: Sáng | BZ4: Trưa | CA4: Chiều | CB4: Sáng | CC4: Trưa | CD4: Chiều | CE4: Sáng | CF4: Trưa | CG4: Chiều | CH4: Sáng | CI4: Trưa | CJ4: Chiều | CK4: Sáng | CL4: Trưa | CM4: Chiều | CN4: Sáng | CO4: Trưa | CP4: Chiều | CQ4: Sáng | CR4: Trưa | CS4: Chiều | CT4: Sáng | CU4: Trưa | CV4: Chiều | CW4: Sáng | CX4: Trưa | CY4: Chiều
B5: =COUNTA(B6:B650) -> 107 | E5: STT
A6: 1 | B6: =IF(C6<>F6,"?","") | C6: 6A | E6: 1 | F6: 6A | G6: 2005929926 | J6: Bon Niêng K' A Ngọc Bé | BI6: Vn | BJ6: Vn | BK6: Vn | BL6: Vn | BM6: Vn | BN6: Vn | BO6: Vn
A7: 2 | B7: =IF(C7<>F7,"?","") | C7: 6A | E7: 2 | F7: 6A | G7: 2005987563 | J7: Phi Srônh Khánh Di | BI7: Vn | BJ7: Vn | BK7: Vn | BL7: Vn | BM7: Vn | BN7: Vn | BO7: Vn
A8: 3 | B8: =IF(C8<>F8,"?","") | C8: 6A | E8: 3 | F8: 6A | G8: 2007861016 | J8: Lơ Mu Phong Đạt | BI8: Vn | BJ8: Vn | BK8: Vn | BL8: Vn | BM8: Vn | BN8: Vn | BO8: Vn
A9: 4 | B9: =IF(C9<>F9,"?","") | C9: 6A | E9: 4 | F9: 6A | G9: 2007275982 | J9: Đa Goút Ngọc Hân | BI9: Vn | BJ9: Vn | BK9: Vn | BL9: Vn | BM9: Vn | BN9: Vn | BO9: Vn
A10: 5 | B10: =IF(C10<>F10,"?","") | C10: 6A | E10: 5 | F10: 6A | G10: 2005932767 | J10: Khổng Hữu Nhật Hưng | U10: vn | V10: vn | W10: vn | X10: vn | BI10: Vn | BJ10: Vn | BK10: Vn | BL10: Vn | BM10: Vn | BN10: Vn | BO10: Vn
A11: 6 | B11: =IF(C11<>F11,"?","") | C11: 6A | E11: 6 | F11: 6A | G11: 2005987564 | J11: Kră Jăn Inly | BI11: Vn | BJ11: Vn | BK11: Vn | BL11: Vn | BM11: Vn | BN11: Vn | BO11: Vn
A12: 7 | B12: =IF(C12<>F12,"?","") | C12: 6A | E12: 7 | F12: 6A | G12: 2007861253 | J12: Kon Sơ Jack Ky | BI12: Vn | BJ12: Vn | BK12: Vn | BL12: Vn | BM12: Vn | BN12: Vn | BO12: Vn
A13: 8 | B13: =IF(C13<>F13,"?","") | C13: 6A | E13: 8 | F13: 6A | G13: 2007282084 | J13: Kơ Să Lê Bê La | BI13: Vn | BJ13: Vn | BK13: Vn | BL13: Vn | BM13: Vn | BN13: Vn | BO13: Vn
A14: 9 | B14: =IF(C14<>F14,"?","") | C14: 6A | E14: 9 | F14: 6A | G14: 2007771303 | J14: Kon Sa Mỹ Lệ | BI14: Vn | BJ14: Vn | BK14: Vn | BL14: Vn | BM14: Vn | BN14: Vn | BO14: Vn
A15: 10 | B15: =IF(C15<>F15,"?","") | C15: 6A | E15: 10 | F15: 6A | G15: 2005987566 | J15: Rơ Ông K' Lộc | BI15: Vn | BJ15: Vn | BK15: Vn | BL15: Vn | BM15: Vn | BN15: Vn | BO15: Vn
A16: 11 | B16: =IF(C16<>F16,"?","") | C16: 6A | E16: 11 | F16: 6A | G16: 2005929465 | J16: Rơ Ông Kim Luôn | BI16: Vn | BJ16: Vn | BK16: Vn | BL16: Vn | BM16: Vn | BN16: Vn | BO16: Vn
A17: 12 | B17: =IF(C17<>F17,"?","") | C17: 6A | E17: 12 | F17: 6A | G17: 2005929092 | J17: Rơ Ông K' Mã | BI17: Vn | BJ17: Vn | BK17: Vn | BL17: Vn | BM17: Vn | BN17: Vn | BO17: Vn
A18: 13 | B18: =IF(C18<>F18,"?","") | C18: 6A | E18: 13 | F18: 6A | G18: 2007281821 | J18: Bon Dơng Ja Min | BI18: Vn | BJ18: Vn | BK18: Vn | BL18: Vn | BM18: Vn | BN18: Vn | BO18: Vn
A19: 14 | B19: =IF(C19<>F19,"?","") | C19: 6A | E19: 14 | F19: 6A | G19: 2007771938 | J19: Kon Sơ Han Na | BI19: Vn | BJ19: Vn | BK19: Vn | BL19: Vn | BM19: Vn | BN19: Vn | BO19: Vn
A20: 15 | B20: =IF(C20<>F20,"?","") | C20: 6A | E20: 15 | F20: 6A | G20: 2007269049 | J20: Kră Jăn Glê Na | AP20: VN | AQ20: VN | AR20: VN | AS20: VN | BI20: Vn | BJ20: Vn | BK20: Vn | BL20: Vn | BM20: Vn | BN20: Vn | BO20: Vn
A21: 16 | B21: =IF(C21<>F21,"?","") | C21: 6A | E21: 16 | F21: 6A | G21: 2005985963 | J21: Kơ Să Phương Nghi | U21: vn | V21: vn | W21: vn | X21: vn | AP21: VN | AQ21: VN | AR21: VN | AS21: VN | BI21: Vn | BJ21: Vn | BK21: Vn | BL21: Vn | BM21: Vn | BN21: Vn | BO21: Vn
A22: 17 | B22: =IF(C22<>F22,"?","") | C22: 6A | E22: 17 | F22: 6A | G22: 2007281822 | J22: Kră Jãn Như Nghiệp | AP22: VN | AQ22: VN | AR22: VN | AS22: VN | BI22: Vn | BJ22: Vn | BK22: Vn | BL22: Vn | BM22: Vn | BN22: Vn | BO22: Vn
A23: 18 | B23: =IF(C23<>F23,"?","") | C23: 6A | E23: 18 | F23: 6A | G23: 2007289895 | J23: Kơ Să An Nhiên | BI23: Vn | BJ23: Vn | BK23: Vn | BL23: Vn | BM23: Vn | BN23: Vn | BO23: Vn
A24: 19 | B24: =IF(C24<>F24,"?","") | C24: 6A | E24: 19 | F24: 6A | G24: 2006022256 | J24: Long Dưng A La Pha | BI24: Vn | BJ24: Vn | BK24: Vn | BL24: Vn | BM24: Vn | BN24: Vn | BO24: Vn
A25: 20 | B25: =IF(C25<>F25,"?","") | C25: 6A | E25: 20 | F25: 6A | G25: 2005930865 | J25: Hoàng Ninh Hải Quân | U25: vn | V25: vn | W25: vn | AP25: VN | AQ25: VN | AR25: VN | AS25: VN | BI25: Vn | BJ25: Vn | BK25: Vn | BL25: Vn | BM25: Vn | BN25: Vn | BO25: Vn
A26: 21 | B26: =IF(C26<>F26,"?","") | C26: 6A | E26: 21 | F26: 6A | G26: 2007779557 | J26: A Dắt Sa Ring | AP26: VN | AQ26: VN | AR26: VN | AS26: VN | BI26: Vn | BJ26: Vn | BK26: Vn | BL26: Vn | BM26: Vn | BN26: Vn | BO26: Vn
A27: 22 | B27: =IF(C27<>F27,"?","") | C27: 6A | E27: 22 | F27: 6A | G27: 2007361108 | J27: Kon Sa Trần Minh Tâm | BI27: Vn | BJ27: Vn | BK27: Vn | BL27: Vn | BM27: Vn | BN27: Vn | BO27: Vn
A28: 23 | B28: =IF(C28<>F28,"?","") | C28: 6A | E28: 23 | F28: 6A | G28: 2007290526 | J28: Kră Jăn Bảo Thi | AP28: VN | AQ28: VN | AR28: VN | AS28: VN | BI28: Vn | BJ28: Vn | BK28: Vn | BL28: Vn | BM28: Vn | BN28: Vn | BO28: Vn
A29: 24 | B29: =IF(C29<>F29,"?","") | C29: 6A | E29: 24 | F29: 6A | G29: 2006770213 | J29: Bon Dưng Gia Thiện | BI29: Vn | BJ29: Vn | BK29: Vn | BL29: Vn | BM29: Vn | BN29: Vn | BO29: Vn
A30: 25 | B30: =IF(C30<>F30,"?","") | C30: 6A | E30: 25 | F30: 6A | G30: 2007774899 | J30: Sohao Phương Thùy | BI30: Vn | BJ30: Vn | BK30: Vn | BL30: Vn | BM30: Vn | BN30: Vn | BO30: Vn
A31: 26 | B31: =IF(C31<>F31,"?","") | C31: 6A | E31: 26 | F31: 6A | G31: 2007281828 | J31: Liêng Jrang Ru Tơ | BI31: Vn | BJ31: Vn | BK31: Vn | BL31: Vn | BM31: Vn | BN31: Vn | BO31: Vn
A32: 54 | B32: =IF(C32<>F32,"?","") | C32: 6A | E32: 27 | F32: 6A | G32: 2007236925 | J32: Rơ Ông K' Thư | AP32: VN | AQ32: VN | AR32: VN | AS32: VN | BI32: Vn | BJ32: Vn | BK32: Vn | BL32: Vn | BM32: Vn | BN32: Vn | BO32: Vn
A33: 27 | B33: =IF(C33<>F33,"?","") | C33: 6A | E33: 28 | F33: 6A | G33: 2007398127 | J33: Bùi Thị Huyền Trâm | BI33: Vn | BJ33: Vn | BK33: Vn | BL33: Vn | BM33: Vn | BN33: Vn | BO33: Vn
A34: 28 | B34: =IF(C34<>F34,"?","") | C34: 6A | E34: 29 | F34: 6A | G34: 2007290534 | J34: Liêng Jrang Lệ Trinh | BI34: Vn | BJ34: Vn | BK34: Vn | BL34: Vn | BM34: Vn | BN34: Vn | BO34: Vn
A35: 29 | B35: =IF(C35<>F35,"?","") | C35: 6B | E35: 1 | F35: 6B | G35: 2005925205 | J35: Trương Văn An | BI35: Vn | BJ35: Vn | BK35: Vn | BL35: Vn | BM35: Vn | BN35: Vn | BO35: Vn
A36: 30 | B36: =IF(C36<>F36,"?","") | C36: 6B | E36: 2 | F36: 6B | G36: 2007291610 | J36: Kră Jăn Ngọc Ánh | AP36: vn | AQ36: vn | AR36: vn | AS36: vn | BI36: Vn | BJ36: Vn | BK36: Vn | BL36: Vn | BM36: Vn | BN36: Vn | BO36: Vn
A37: 31 | B37: =IF(C37<>F37,"?","") | C37: 6B | E37: 3 | F37: 6B | G37: 2005985972 | J37: Liêng Hót Dêbôra | S37: VN | T37: VN | U37: VN | V37: VN | W37: VN | X37: VN | AP37: vn | AQ37: vn | AR37: vn | AS37: vn | BI37: Vn | BJ37: Vn | BK37: Vn | BL37: Vn | BM37: Vn | BN37: Vn | BO37: Vn
A38: 32 | B38: =IF(C38<>F38,"?","") | C38: 6B | E38: 4 | F38: 6B | G38: 2005927229 | J38: Bon Niêng K' Gưm | AP38: vn | AQ38: vn | AR38: vn | AS38: vn | BI38: Vn | BJ38: Vn | BK38: Vn | BL38: Vn | BM38: Vn | BN38: Vn | BO38: Vn
A39: 33 | B39: =IF(C39<>F39,"?","") | C39: 6B | E39: 5 | F39: 6B | G39: 2006153308 | J39: Đà Cắt K' Na Hi | AP39: vn | AQ39: vn | AR39: vn | AS39: vn | BI39: Vn | BJ39: Vn | BK39: Vn | BL39: Vn | BM39: Vn | BN39: Vn | BO39: Vn
A40: 34 | B40: =IF(C40<>F40,"?","") | C40: 6B | E40: 6 | F40: 6B | G40: 2006027380 | J40: Chu Nhật Huy | BI40: Vn | BJ40: Vn | BK40: Vn | BL40: Vn | BM40: Vn | BN40: Vn | BO40: Vn
A41: 35 | B41: =IF(C41<>F41,"?","") | C41: 6B | E41: 7 | F41: 6B | G41: 2009200496 | J41: Lơ Mu Julia | AP41: vn | AQ41: vn | AR41: vn | AS41: vn | BI41: Vn | BJ41: Vn | BK41: Vn | BL41: Vn | BM41: Vn | BN41: Vn | BO41: Vn
...

Sheet Bản sao của DS HS không ăn
J1: Tháng 12 / 2024
J2: Ngày | K2: 1 | N2: 2 | Q2: 3 | T2: 4 | W2: 5 | Z2: 6 | AC2: 7 | AD2: 7 | AE2: 7 | AF2: 8 | AG2: 8 | AH2: 8 | AI2: 9 | AL2: 10 | AO2: 11 | AR2: 12 | AU2: 13 | AX2: 14 | BA2: 15 | BD2: 16 | BG2: 17 | BJ2: 18 | BM2: 19 | BP2: 20 | BS2: 21 | BV2: 22 | BY2: 23 | CB2: 24 | CE2: 25 | CH2: 26 | CK2: 27 | CN2: 28 | CQ2: 29 | CR2: 29 | CS2: 29 | CT2: 30 | CU2: 30 | CV2: 30 | CW2: 31 | CX2: 31 | CY2: 31
F3: =COUNTA(F6:F645) -> 638 | J3: Thứ | K3: CN | N3: Hai | Q3: Ba | T3: Tư | W3: Năm | Z3: Sáu | AC3: Bảy | AD3: Bảy | AE3: Bảy | AF3: CN | AG3: CN | AH3: CN | AI3: Hai | AL3: Ba | AO3: Tư | AR3: Năm | AU3: Sáu | AX3: Bảy | BA3: CN | BD3: Hai | BG3: Ba | BJ3: Tư | BM3: Năm | BP3: Sáu | BS3: Bảy | BV3: CN | BY3: Hai | CB3: Ba | CE3: Tư | CH3: Năm | CK3: Sáu | CL3: Sáu | CM3: Sáu | CN3: Bảy | CO3: Bảy | CP3: Bảy | CQ3: CN | CR3: CN | CS3: CN | CT3: Hai | CW3: Ba
A4: STT | B4: KT lớp | F4: Lớp | G4: Mã học sinh | H4: Mã MOET | I4: Số định danh | J4: Họ và tên | K4: Sáng | L4: Trưa | M4: Chiều | N4: Sáng | O4: Trưa | P4: Chiều | Q4: Sáng | R4: Trưa | S4: Chiều | T4: Sáng | U4: Trưa | V4: Chiều | W4: Sáng | X4: Trưa | Y4: Chiều | Z4: Sáng | AA4: Trưa | AB4: Chiều | AC4: Sáng | AD4: Trưa | AE4: Chiều | AF4: Sáng | AG4: Trưa | AH4: Chiều | AI4: Sáng | AJ4: Trưa | AK4: Chiều | AL4: Sáng | AM4: Trưa | AN4: Chiều | AO4: Sáng | AP4: Trưa | AQ4: Chiều | AR4: Sáng | AS4: Trưa | AT4: Chiều | AU4: Sáng | AV4: Trưa | AW4: Chiều | AX4: Sáng | AY4: Trưa | AZ4: Chiều | BA4: Sáng | BB4: Trưa | BC4: Chiều | BD4: Sáng | BE4: Trưa | BF4: Chiều | BG4: Sáng | BH4: Trưa | BI4: Chiều | BJ4: Sáng | BK4: Trưa | BL4: Chiều | BM4: Sáng | BN4: Trưa | BO4: Chiều | BP4: Sáng | BQ4: Trưa | BR4: Chiều | BS4: Sáng | BT4: Trưa | BU4: Chiều | BV4: Sáng | BW4: Trưa | BX4: Chiều | BY4: Sáng | BZ4: Trưa | CA4: Chiều | CB4: Sáng | CC4: Trưa | CD4: Chiều | CE4: Sáng | CF4: Trưa | CG4: Chiều | CH4: Sáng | CI4: Trưa | CJ4: Chiều | CK4: Sáng | CL4: Trưa | CM4: Chiều | CN4: Sáng | CO4: Trưa | CP4: Chiều | CQ4: Sáng | CR4: Trưa | CS4: Chiều | CT4: Sáng | CU4: Trưa | CV4: Chiều | CW4: Sáng | CX4: Trưa | CY4: Chiều
E5: STT
A6: 1 | B6: =IF(C6=F6,"","?") | C6: 6A | D6: =IF(C6=C5,D5+1,1) -> 1 | E6: 1 | F6: 6A | G6: 2003011968 | H6: 6870987192 | I6: 68313006414 | J6: Kră Jẵn Da Lia A | AE6: về nhà | AF6: về nhà | AG6: về nhà
A7: 2 | B7: =IF(C7=F7,"","?") | C7: 6A | D7: =IF(C7=C6,D6+1,1) -> 2 | E7: 2 | F7: 6A | G7: 2007266660 | H7: 6839557963 | I7: 68313001040 | J7: Da Gout Lê An | AG7: đi ăn với PH
A8: 3 | B8: =IF(C8=F8,"","?") | C8: 6A | D8: =IF(C8=C7,D7+1,1) -> 3 | E8: 3 | F8: 6A | G8: 2003016149 | H8: 6884337059 | I8: 68213001414 | J8: Ntôl Bùi Thiên Ân | AG8: đi ăn với PH
A9: 4 | B9: =IF(C9=F9,"","?") | C9: 6A | D9: =IF(C9=C8,D8+1,1) -> 4 | E9: 4 | F9: 6A | G9: 2003015070 | H9: 6884337061 | I9: 68313008361 | J9: Kơ Să Catherine | AG9: đi ăn với PH
A10: 5 | B10: =IF(C10=F10,"","?") | C10: 6A | D10: =IF(C10=C9,D9+1,1) -> 5 | E10: 5 | F10: 6A | G10: 2003007509 | H10: 6884337062 | I10: 68313005641 | J10: Kon Sơ Minh Châu | AG10: đi ăn với PH
A11: 6 | B11: =IF(C11=F11,"","?") | C11: 6A | D11: =IF(C11=C10,D10+1,1) -> 6 | E11: 6 | F11: 6A | G11: 2007266667 | H11: 6839561127 | I11: 68313008475 | J11: Cil Múp La Dy | AE11: đi ăn với PH | AG11: đi ăn với PH
A12: 7 | B12: =IF(C12=F12,"","?") | C12: 6A | D12: =IF(C12=C11,D11+1,1) -> 7 | E12: 7 | F12: 6A | G12: 2003014813 | H12: 6857524934 | I12: 68213005595 | J12: Kơ Să Hê Grin | AG12: đi ăn với PH
A13: 8 | B13: =IF(C13=F13,"","?") | C13: 6A | D13: =IF(C13=C12,D12+1,1) -> 8 | E13: 8 | F13: 6A | G13: 2003016195 | H13: 6884337063 | I13: 68313008744 | J13: Dơng Gur Si Kha | AG13: đi ăn với PH
A14: 9 | B14: =IF(C14=F14,"","?") | C14: 6A | D14: =IF(C14=C13,D13+1,1) -> 9 | E14: 9 | F14: 6A | G14: 2003007491 | H14: 6878019274 | I14: 68213010984 | J14: Kơ Să Nông Tiến Khoa | AG14: đi ăn với PH
A15: 10 | B15: =IF(C15=F15,"","?") | C15: 6A | D15: =IF(C15=C14,D14+1,1) -> 10 | E15: 10 | F15: 6A | G15: 2003016199 | H15: 6884337064 | I15: 68313003847 | J15: Kon Sa The Kô | AG15: đi ăn với PH
A16: 11 | B16: =IF(C16=F16,"","?") | C16: 6A | D16: =IF(C16=C15,D15+1,1) -> 11 | E16: 11 | F16: 6A | G16: 2001227492 | H16: 6878153419 | I16: 68213005916 | J16: Dơng Gur Ha Krơng | AG16: đi ăn với PH
A17: 12 | B17: =IF(C17=F17,"","?") | C17: 6A | D17: =IF(C17=C16,D16+1,1) -> 12 | E17: 12 | F17: 6A | G17: 2007250577 | H17: 6844474140 | I17: 68313007622 | J17: Klong Như Lan | AG17: đi ăn với PH
A18: 13 | B18: =IF(C18=F18,"","?") | C18: 6A | D18: =IF(C18=C17,D17+1,1) -> 13 | E18: 13 | F18: 6A | G18: 2007266483 | H18: 6844474196 | I18: 68313008509 | J18: Rơ Ông K' Le | AG18: đi ăn với PH
A19: 14 | B19: =IF(C19=F19,"","?") | C19: 6A | D19: =IF(C19=C18,D18+1,1) -> 14 | E19: 14 | F19: 6A | G19: 2003011956 | H19: 6844806319 | I19: 68313001061 | J19: Kră Jăn K' Linh | AE19: về nhà | AF19: về nhà | AG19: về nhà
A20: 15 | B20: =IF(C20=F20,"","?") | C20: 6A | D20: =IF(C20=C19,D19+1,1) -> 15 | E20: 15 | F20: 6A | G20: 2006153766 | H20: 6884337065 | I20: 68313008703 | J20: Klong K' Loan | AG20: đi ăn với PH
A21: 16 | B21: =IF(C21=F21,"","?") | C21: 6A | D21: =IF(C21=C20,D20+1,1) -> 16 | E21: 16 | F21: 6A | G21: 2003016119 | H21: 6884337066 | I21: 68213012066 | J21: Rơ Ông Ha Luis | AE21: đi ăn với PH | AG21: đi ăn với PH
A22: 17 | B22: =IF(C22=F22,"","?") | C22: 6A | D22: =IF(C22=C21,D21+1,1) -> 17 | E22: 17 | F22: 6A | G22: 2003011884 | H22: 6848391598 | I22: 68313014239 | J22: Kon Sơ K' Khên Ly | AE22: về nhà | AF22: về nhà | AG22: về nhà
A23: 18 | B23: =IF(C23=F23,"","?") | C23: 6A | D23: =IF(C23=C22,D22+1,1) -> 18 | E23: 18 | F23: 6A | G23: 2003007482 | H23: 6802301416 | I23: 68213011901 | J23: Cil Pam Khôi Nguyên | AE23: về nhà | AF23: về nhà | AG23: về nhà
A24: 19 | B24: =IF(C24=F24,"","?") | C24: 6A | D24: =IF(C24=C23,D23+1,1) -> 19 | E24: 19 | F24: 6A | G24: 2006153788 | H24: 6858294710 | I24: 68313005805 | J24: Pang Ting Trắng Thu Nguyệt | AE24: về nhà | AF24: về nhà | AG24: về nhà
A25: 20 | B25: =IF(C25=F25,"","?") | C25: 6A | D25: =IF(C25=C24,D24+1,1) -> 20 | E25: 20 | F25: 6A | G25: 2009201989 | H25: 6804793994 | I25: 17213010875 | J25: Bạch Pang Thiện Nhân | AE25: về nhà | AF25: về nhà | AG25: về nhà
A26: 21 | B26: =IF(C26=F26,"","?") | C26: 6A | D26: =IF(C26=C25,D25+1,1) -> 21 | E26: 21 | F26: 6A | G26: 2007115913 | H26: 6840162672 | I26: 68213006387 | J26: Cêl Môp Rơ Ông Nhuận | AE26: đi ăn với PH | AG26: đi ăn với PH
A27: 22 | B27: =IF(C27=F27,"","?") | C27: 6A | D27: =IF(C27=C26,D26+1,1) -> 22 | E27: 22 | F27: 6A | G27: 2006163697 | H27: 6884337068 | I27: 68313012294 | J27: Rơ Ông Kỳ Phương | AG27: đi ăn với PH
A28: 23 | B28: =IF(C28=F28,"","?") | C28: 6A | D28: =IF(C28=C27,D27+1,1) -> 23 | E28: 23 | F28: 6A | G28: 2006153773 | H28: 6884337069 | I28: 68313008746 | J28: Cil The Ry | AG28: đi ăn với PH
A29: 24 | B29: =IF(C29=F29,"","?") | C29: 6A | D29: =IF(C29=C28,D28+1,1) -> 24 | E29: 24 | F29: 6A | G29: 2003012385 | H29: 6870986428 | I29: 68213002414 | J29: Kră Jãn Na Than | AE29: về nhà | AF29: về nhà | AG29: về nhà
A30: 25 | B30: =IF(C30=F30,"","?") | C30: 6A | D30: =IF(C30=C29,D29+1,1) -> 25 | E30: 25 | F30: 6A | G30: 2003014839 | H30: 6841159824 | I30: 68313003461 | J30: Bon Dơng Lê Thiên | AG30: đi ăn với PH
A31: 26 | B31: =IF(C31=F31,"","?") | C31: 6A | D31: =IF(C31=C30,D30+1,1) -> 26 | E31: 26 | F31: 6A | G31: 2007266638 | H31: 6855815162 | I31: 68213006448 | J31: Klong Đức Thuận | AE31: về nhà | AF31: về nhà | AG31: về nhà
A32: 27 | B32: =IF(C32=F32,"","?") | C32: 6A | D32: =IF(C32=C31,D31+1,1) -> 27 | E32: 27 | F32: 6A | G32: 2003007504 | H32: 6878019283 | I32: 68313004149 | J32: Kơ Să Nông Thị Trang | AE32: về nhà | AF32: về nhà | AG32: về nhà
A33: 28 | B33: =IF(C33=F33,"","?") | C33: 6A | D33: =IF(C33=C32,D32+1,1) -> 28 | E33: 28 | F33: 6A | G33: 2003016166 | H33: 6884337070 | I33: 68313004880 | J33: Cil Múp Huyền Trân | AG33: đi ăn với PH
A34: 29 | B34: =IF(C34=F34,"","?") | C34: 6A | D34: =IF(C34=C33,D33+1,1) -> 29 | E34: 29 | F34: 6A | G34: 2003014922 | H34: 6841189638 | I34: 68313010734 | J34: Cil Yũ K' Hải Yến | AG34: đi ăn với PH
A35: 30 | B35: =IF(C35=F35,"","?") | C35: 6B | D35: =IF(C35=C34,D34+1,1) -> 1 | E35: 1 | F35: 6B | G35: 2007266665 | H35: 6884660085 | I35: 68313012356 | J35: Kră Jañ Ra Chel | AE35: ĐI LỄ | AG35: Đi với ph
A36: 31 | B36: =IF(C36=F36,"","?") | C36: 6B | D36: =IF(C36=C35,D35+1,1) -> 2 | E36: 2 | F36: 6B | G36: 2003016118 | H36: 6884337184 | I36: 68313010493 | J36: Cil Múp My Rin Da
A37: 32 | B37: =IF(C37=F37,"","?") | C37: 6B | D37: =IF(C37=C36,D36+1,1) -> 3 | E37: 3 | F37: 6B | G37: 2003016112 | H37: 6884337185 | I37: 68213008583 | J37: Ntôl Ha Dân | AE37: ĐI LỄ | AG37: Đi với ph
A38: 33 | B38: =IF(C38=F38,"","?") | C38: 6B | D38: =IF(C38=C37,D37+1,1) -> 4 | E38: 4 | F38: 6B | G38: 2003012369 | H38: 6870987105 | I38: 68313005559 | J38: Kră Jăn K' Linh Đan | AG38: Đi với ph
A39: 34 | B39: =IF(C39=F39,"","?") | C39: 6B | D39: =IF(C39=C38,D38+1,1) -> 5 | E39: 5 | F39: 6B | G39: 2006164505 | H39: 6884337186 | I39: 68313007286 | J39: K' Hi | AE39: ĐI LỄ | AG39: Đi với ph
A40: 35 | B40: =IF(C40=F40,"","?") | C40: 6B | D40: =IF(C40=C39,D39+1,1) -> 6 | E40: 6 | F40: 6B | G40: 2003015048 | H40: 6841422869 | I40: 68213003815 | J40: Cao Kon Sơ Song Hỉ | AE40: ĐI LỄ | AG40: Đi với ph
...

Sheet BHYT old
A1: Stt | B1: Lớp | F1: Họ và tên | G1: Ngày tháng năm sinh | H1: Giới tính | I1: Số căn cước (hoặc mã định danh) | J1: Mã đối tượng (vd: HS, DT, HN,…) | K1: Mã số BHYT (10 số) | L1: Nơi đăng ký khám chữa bệnh ban đầu | M1: Hạn thẻ | N1: Địa chỉ nơi cư trú (địa chỉ cũ)
A2: 1 | B2: 6A | C2: 2005929926 | D2: Bon Niêng K' A Ngọc | E2: Bé | F2: Bon Niêng K' A Ngọc Bé | G2: 41880 | H2: Nữ | I2: 68314012551
A3: 2 | B3: 6A | C3: 2005987563 | D3: Phi Srônh Khánh | E3: Di | F3: Phi Srônh Khánh Di | G3: 41921 | H3: Nữ | I3: 68314011299
A4: 3 | B4: 6A | C4: 2007861016 | D4: Lơ Mu Phong | E4: Đạt | F4: Lơ Mu Phong Đạt | G4: 41640 | H4: Nam | I4: 68214012739
A5: 4 | B5: 6A | C5: 2007275982 | D5: Đa Goút Ngọc | E5: Hân | F5: Đa Goút Ngọc Hân | G5: 41964 | H5: Nữ | I5: 68314008738
A6: 5 | B6: 6A | C6: 2005932767 | D6: Khổng Hữu Nhật | E6: Hưng | F6: Khổng Hữu Nhật Hưng | G6: 41827 | H6: Nam | I6: 68214008449
A7: 6 | B7: 6A | C7: 2005987564 | D7: Kră Jăn | E7: Inly | F7: Kră Jăn Inly | G7: 41771 | H7: Nữ | I7: 68314005263
A8: 7 | B8: 6A | C8: 2007861253 | D8: Kon Sơ Jack | E8: Ky | F8: Kon Sơ Jack Ky | G8: 41667 | H8: Nam | I8: 68214006126
A9: 8 | B9: 6A | C9: 2007282084 | D9: Kơ Să Lê Bê | E9: La | F9: Kơ Să Lê Bê La | G9: 41822 | H9: Nữ | I9: 68314004312
A10: 9 | B10: 6A | C10: 2007771303 | D10: Kon Sa Mỹ | E10: Lệ | F10: Kon Sa Mỹ Lệ | G10: 41786 | H10: Nữ | I10: 68314011169
A11: 10 | B11: 6A | C11: 2005987566 | D11: Rơ Ông K' | E11: Lộc | F11: Rơ Ông K' Lộc | G11: 41918 | H11: Nam | I11: 68214008536
A12: 11 | B12: 6A | C12: 2005929465 | D12: Rơ Ông Kim | E12: Luôn | F12: Rơ Ông Kim Luôn | G12: 41672 | H12: Nữ | I12: 68314011089
A13: 12 | B13: 6A | C13: 2005929092 | D13: Rơ Ông K' | E13: Mã | F13: Rơ Ông K' Mã | G13: 41951 | H13: Nữ | I13: 68314008959
... A121: 120 | B121: 8A | C121: 2305220417 | D121: Lơ Mu | E121: Hanna | F121: Lơ Mu Hanna | G121: 40988 | H121: Nữ | I121: 68312010247
A122: 121 | B122: 8A | C122: 2305235648 | D122: Bon Niêng K' | E122: Hảo | F122: Bon Niêng K' Hảo | G122: 40919 | H122: Nữ
A123: 122 | B123: 8A | C123: 2305229049 | D123: Kơ Să Mỹ | E123: Hiền | F123: Kơ Să Mỹ Hiền | G123: 41207 | H123: Nữ | I123: 68312001207
A124: 123 | B124: 8A | C124: 2305235841 | D124: Kơ Să Ly Su | E124: In | F124: Kơ Să Ly Su In | G124: 41190 | H124: Nữ | I124: 68312010088
A125: 124 | B125: 8A | C125: 2305236349 | D125: Rơ ông Siu | E125: Ly | F125: Rơ ông Siu Ly | G125: 41192 | H125: Nữ | I125: 68312008245
A126: 125 | B126: 8A | C126: 2305240330 | D126: Kon Sa Na Ô | E126: Mi | F126: Kon Sa Na Ô Mi | G126: 41239 | H126: Nữ | I126: 68312014695
A127: 126 | B127: 8A | C127: 2305230258 | D127: Cil Pam Thiết | E127: Nghiêm | F127: Cil Pam Thiết Nghiêm | G127: 41258 | H127: Nam | I127: 68212009059
A128: 127 | B128: 8A | C128: 2305218180 | D128: Klong Kim | E128: Ngọc | F128: Klong Kim Ngọc | G128: 40935 | H128: Nữ | I128: 68312004022
A129: 128 | B129: 8A | C129: 2305240119 | D129: Pang Ting Nguyễn Bảo | E129: Ngọc | F129: Pang Ting Nguyễn Bảo Ngọc | G129: 40944 | H129: Nữ | I129: 68312005102
A130: 129 | B130: 8A | C130: 2305219012 | D130: Da Căt Huy | E130: Nhật | F130: Da Căt Huy Nhật | G130: 41234 | H130: Nam | I130: 68212003199
A131: 130 | B131: 8A | C131: 2305231757 | D131: Lơ Mu Siu | E131: Niệm | F131: Lơ Mu Siu Niệm | G131: 41139 | H131: Nữ | I131: 68312009326
A132: 131 | B132: 8A | C132: 2305212358 | D132: Păng Ting K' Builly | E132: Pốt | F132: Păng Ting K' Builly Pốt | G132: 40976 | H132: Nữ | I132: 68312003415
A133: 132 | B133: 8A | C133: 2305210128 | D133: Kră Jăn Ju | E133: Rin | F133: Kră Jăn Ju Rin | G133: 41059 | H133: Nữ | I133: 68312010567
A134: 133 | B134: 8A | C134: 2305216846 | D134: Kơ Să K' | E134: Thao | F134: Kơ Să K' Thao | G134: 41214 | H134: Nam | I134: 68212010095
... A652: 651 | B652: 12C3 | C652: 2001128249 | D652: Ka | E652: Vy | F652: Ka Vy | G652: 39661 | H652: Nữ | I652: 68308000060

Sheet 2526_Ds toan truong
A1: Stt | H1: Họ và tên | I1: Ngày tháng năm sinh | J1: Giới tính | K1: Số căn cước (hoặc mã định danh) | M1: Mã đối tượng (vd: HS, DT, HN,…) | N1: Mã số BHYT (10 số) | O1: Nơi đăng ký khám chữa bệnh ban đầu | P1: Hạn thẻ | Q1: Địa chỉ nơi cư trú (địa chỉ cũ)
A4: STT | B4: Lớp học | C4: Mã học sinh | D4: Mã MOET | E4: Sổ đăng bộ | F4: Họ và | G4: tên | I4: Ngày sinh | J4: Giới tính | K4: Căn cước | L4: Chỗ ở hiện nay | P4: Hộ khẩu thường trú | T4: Nơi sinh | W4: Quê quán | Z4: Căn cước | AA4: Ngày cấp Căn cước | AB4: Nơi cấp Căn cước | AC4: Dân tộc | AD4: Tôn giáo | AE4: Diện chính sách | AF4: Cận nghèo | AG4: Đoàn viên | AH4: Đội viên | AI4: Tên cha | AJ4: Nghề nghiệp cha | AK4: Năm sinh cha | AL4: Tên mẹ | AM4: Nghề nghiệp mẹ | AN4: Năm sinh mẹ | AO4: Điện thoại SLL | AP4: Email SLL | AQ4: Điện thoại bố | AR4: Điện thoại mẹ | AS4: Ghi chú
L5: SN/Xóm | M5: Khu dân cư | N5: Xã/Phường | O5: Tỉnh/Tp | P5: SN/Xóm | Q5: Khu dân cư | R5: Xã/Phường | S5: Tỉnh/Tp | T5: Thông tin nơi sinh | U5: Xã/Phường | V5: Tỉnh/Tp | W5: Thông tin quê quán | X5: Xã/Phường | Y5: Tỉnh/Tp
A6: 1 | B6: 6A | C6: 2005929926 | E6: 1 | F6: Bon Niêng K' A Ngọc | G6: Bé | H6: Bon Niêng K' A Ngọc Bé | I6: 41880 | J6: Nữ | K6: 68314012551 | L6: Thôn 1 | M6: Thôn K'Nớ 1 | N6: Xã Đam Rông 4 | O6: Lâm Đồng | Q6: Thôn K'Nớ 1 | U6: Xã Đam Rông 4 | V6: Lâm Đồng | Z6: 68314012551 | AC6: Cơ-ho | AD6: Không | AF6: 0 | AG6: 0 | AH6: 0 | AO6: 966422725
A7: 2 | B7: 6A | C7: 2005987563 | E7: 2 | F7: Phi Srônh Khánh | G7: Di | H7: Phi Srônh Khánh Di | I7: 41921 | J7: Nữ | K7: 68314011299 | L7: Thôn Păng Tiêng | N7: Phường Lang Biang - Đà Lạt | O7: Lâm Đồng | Z7: 68314011299 | AC7: Cơ-ho | AD7: Không | AF7: 0 | AG7: 0 | AH7: 0 | AO7: 334023997
A8: 3 | B8: 6A | C8: 2007861016 | E8: 3 | F8: Lơ Mu Phong | G8: Đạt | H8: Lơ Mu Phong Đạt | I8: 41640 | J8: Nam | K8: 68214012739 | L8: Liêng Bông | N8: Xã Lạc Dương | O8: Lâm Đồng | Z8: 68214012739 | AC8: Cơ-ho | AD8: Không | AF8: 0 | AG8: 0 | AH8: 0
A9: 4 | B9: 6A | C9: 2007275982 | E9: 4 | F9: Đa Goút Ngọc | G9: Hân | H9: Đa Goút Ngọc Hân | I9: 41964 | J9: Nữ | K9: 68314008738 | L9: Tổ 17, Thôn 3 | M9: Thôn 3 | N9: Phường Cam Ly - Đà Lạt | O9: Lâm Đồng | Q9: Thôn 3 | V9: Lâm Đồng | Z9: 68314008738 | AC9: Cơ-ho | AD9: Không | AF9: 0 | AG9: 0 | AH9: 0 | AO9: 348605043
A10: 5 | B10: 6A | C10: 2005932767 | E10: 5 | F10: Khổng Hữu Nhật | G10: Hưng | H10: Khổng Hữu Nhật Hưng | I10: 41827 | J10: Nam | K10: 68214008449 | L10: Thôn 2 | M10: Thôn K'Nớ 2 | N10: Xã Đam Rông 4 | O10: Lâm Đồng | Q10: Thôn K'Nớ 2 | U10: Xã Đam Rông 4 | V10: Lâm Đồng | Z10: 68214008449 | AC10: Hoa | AD10: Không | AF10: 0 | AG10: 0 | AH10: 0 | AO10: 966440636
A11: 6 | B11: 6A | C11: 2005987564 | E11: 6 | F11: Kră Jăn | G11: Inly | H11: Kră Jăn Inly | I11: 41771 | J11: Nữ | K11: 68314005263 | L11: Thôn Păng Tiêng | N11: Phường Lang Biang - Đà Lạt | O11: Lâm Đồng | Z11: 68314005263 | AC11: Cơ-ho | AD11: Không | AF11: 0 | AG11: 0 | AH11: 0 | AO11: 966091442
A12: 7 | B12: 6A | C12: 2007861253 | E12: 7 | F12: Kon Sơ Jack | G12: Ky | H12: Kon Sơ Jack Ky | I12: 41667 | J12: Nam | K12: 68214006126 | L12: Đa Hoa | N12: Xã Lạc Dương | O12: Lâm Đồng | Z12: 68214006126 | AC12: Cơ-ho | AD12: Không | AF12: 0 | AG12: 0 | AH12: 0
A13: 8 | B13: 6A | C13: 2007282084 | E13: 8 | F13: Kơ Să Lê Bê | G13: La | H13: Kơ Să Lê Bê La | I13: 41822 | J13: Nữ | K13: 68314004312 | L13: Thôn 1 | N13: Xã Lạc Dương | O13: Lâm Đồng | Z13: 68314004312 | AC13: Cil | AD13: Không | AF13: 0 | AG13: 0 | AH13: 0 | AO13: 888740887
A14: 9 | B14: 6A | C14: 2007771303 | E14: 9 | F14: Kon Sa Mỹ | G14: Lệ | H14: Kon Sa Mỹ Lệ | I14: 41786 | J14: Nữ | K14: 68314011169 | L14: Đa Blah | N14: Xã Lạc Dương | O14: Lâm Đồng | Z14: 68314011169 | AC14: Cơ-ho | AD14: Không | AF14: 0 | AG14: 0 | AH14: 0 | AO14: 388011924
A15: 10 | B15: 6A | C15: 2005987566 | E15: 10 | F15: Rơ Ông K' | G15: Lộc | H15: Rơ Ông K' Lộc | I15: 41918 | J15: Nam | K15: 68214008536 | L15: Thôn Păng Tiêng | N15: Phường Lang Biang - Đà Lạt | O15: Lâm Đồng | Z15: 68214008536 | AC15: Cơ-ho | AD15: Không | AF15: 0 | AG15: 0 | AH15: 0 | AO15: 961856042
A16: 11 | B16: 6A | C16: 2005929465 | E16: 11 | F16: Rơ Ông Kim | G16: Luôn | H16: Rơ Ông Kim Luôn | I16: 41672 | J16: Nữ | K16: 68314011089 | L16: Thôn 1 | M16: Thôn K'Nớ 1 | N16: Xã Đam Rông 4 | O16: Lâm Đồng | Q16: Thôn K'Nớ 1 | U16: Xã Đam Rông 4 | V16: Lâm Đồng | Z16: 68314011089 | AC16: Cơ-ho | AD16: Không | AF16: 0 | AG16: 0 | AH16: 0 | AO16: 374569021
A17: 12 | B17: 6A | C17: 2005929092 | E17: 12 | F17: Rơ Ông K' | G17: Mã | H17: Rơ Ông K' Mã | I17: 41951 | J17: Nữ | K17: 68314008959 | L17: Thôn 1 | M17: Thôn K'Nớ 1 | N17: Xã Đam Rông 4 | O17: Lâm Đồng | Q17: Thôn K'Nớ 1 | Z17: 68314008959 | AC17: Cơ-ho | AD17: Không | AF17: 0 | AG17: 0 | AH17: 0 | AO17: 968926721
A18: 13 | B18: 6A | C18: 2007281821 | E18: 13 | F18: Bon Dơng Ja | G18: Min | H18: Bon Dơng Ja Min | I18: 41950 | J18: Nam | K18: 68214007220 | L18: Thôn 5 | N18: Xã Lạc Dương | O18: Lâm Đồng | Z18: 68214007220 | AC18: Cil | AD18: Không | AF18: 0 | AG18: 0 | AH18: 0 | AO18: 328463923
A19: 14 | B19: 6A | C19: 2007771938 | E19: 14 | F19: Kon Sơ Han | G19: Na | H19: Kon Sơ Han Na | I19: 41740 | J19: Nữ | K19: 68214001702 | L19: Liêng Bông | N19: Xã Lạc Dương | O19: Lâm Đồng | Z19: 68214001702 | AC19: Cơ-ho | AD19: Không | AF19: 0 | AG19: 0 | AH19: 0 | AO19: 363778641
A20: 15 | B20: 6A | C20: 2007269049 | E20: 15 | F20: Kră Jăn Glê | G20: Na | H20: Kră Jăn Glê Na | I20: 41642 | J20: Nữ | K20: 68314005469 | L20: Thị trấn Lạc Dương | M20: Tổ dân phố Đang Kia | N20: Phường Lang Biang - Đà Lạt | O20: Lâm Đồng | Q20: Tổ dân phố Đang Kia | Z20: 68314005469 | AC20: Cơ-ho | AD20: Không | AF20: 0 | AG20: 0 | AH20: 0 | AO20: 965615930
A21: 16 | B21: 6A | C21: 2005985963 | E21: 16 | F21: Kơ Să Phương | G21: Nghi | H21: Kơ Să Phương Nghi | I21: 41846 | J21: Nữ | K21: 68314004478 | L21: Thôn Đạ Nghịt | N21: Phường Lang Biang - Đà Lạt | O21: Lâm Đồng | Z21: 68314004478 | AC21: Cil | AD21: Không | AF21: 0 | AG21: 0 | AH21: 0 | AO21: 388224194
A22: 17 | B22: 6A | C22: 2007281822 | E22: 17 | F22: Kră Jãn Như | G22: Nghiệp | H22: Kră Jãn Như Nghiệp | I22: 41921 | J22: Nữ | K22: 68314004554 | L22: Thôn 3 | N22: Xã Lạc Dương | O22: Lâm Đồng | U22: Xã Lạc Dương | V22: Lâm Đồng | Z22: 68314004554 | AC22: Cil | AD22: Không | AF22: 0 | AG22: 0 | AH22: 0 | AO22: 383024906
A23: 18 | B23: 6A | C23: 2007289895 | E23: 18 | F23: Kơ Să An | G23: Nhiên | H23: Kơ Să An Nhiên | I23: 41640 | J23: Nữ | K23: 68314005823 | L23: Thôn Tu Poh | N23: Xã Lạc Dương | O23: Lâm Đồng | Z23: 68314005823 | AC23: Cil | AD23: Không | AF23: 0 | AG23: 0 | AH23: 0
A24: 19 | B24: 6A | C24: 2006022256 | E24: 19 | F24: Long Dưng A La | G24: Pha | H24: Long Dưng A La Pha | I24: 41850 | J24: Nữ | K24: 68314008751 | L24: Thôn Lán Tranh | M24: Thôn Lán Tranh | N24: Xã Đam Rông 4 | O24: Lâm Đồng | Q24: Thôn Lán Tranh | U24: Xã Đam Rông 4 | V24: Lâm Đồng | Z24: 68314008751 | AC24: Cơ-ho | AD24: Không | AF24: 0 | AG24: 0 | AH24: 0 | AO24: 369493081
A25: 20 | B25: 6A | C25: 2005930865 | E25: 20 | F25: Hoàng Ninh Hải | G25: Quân | H25: Hoàng Ninh Hải Quân | I25: 41697 | J25: Nam | K25: 68214006117 | L25: Thôn 2 | M25: Thôn K'Nớ 2 | N25: Xã Đam Rông 4 | O25: Lâm Đồng | Q25: Thôn K'Nớ 2 | U25: Xã Đam Rông 4 | V25: Lâm Đồng | Z25: 68214006117 | AD25: Không | AF25: 0 | AG25: 0 | AH25: 0 | AO25: 395795081
A26: 21 | B26: 6A | C26: 2007779557 | E26: 21 | F26: A Dắt Sa | G26: Ring | H26: A Dắt Sa Ring | I26: 41960 | J26: Nữ | K26: 68314010442 | L26: Thôn Đa Hoa | N26: Xã Lạc Dương | O26: Lâm Đồng | Z26: 68314010442 | AC26: Cơ-ho | AD26: Không | AF26: 0 | AG26: 0 | AH26: 0
A27: 22 | B27: 6A | C27: 2007361108 | E27: 22 | F27: Kon Sa Trần Minh | G27: Tâm | H27: Kon Sa Trần Minh Tâm | I27: 41960 | J27: Nữ | K27: 68314008947 | L27: Thôn Long Lanh | N27: Xã Lạc Dương | O27: Lâm Đồng | Z27: 68314008947 | AC27: Cơ-ho | AD27: Không | AF27: 0 | AG27: 0 | AH27: 0
A28: 23 | B28: 6A | C28: 2007290526 | E28: 23 | F28: Kră Jăn Bảo | G28: Thi | H28: Kră Jăn Bảo Thi | I28: 41736 | J28: Nữ | K28: 68314006827 | L28: Thôn 1 | N28: Xã Lạc Dương | O28: Lâm Đồng | Z28: 68314006827 | AC28: Cil | AD28: Không | AF28: 0 | AG28: 0 | AH28: 0 | AO28: 329175949
A29: 24 | B29: 6A | C29: 2006770213 | E29: 24 | F29: Bon Dưng Gia | G29: Thiện | H29: Bon Dưng Gia Thiện | I29: 41989 | J29: Nam | K29: 68214000834 | L29: Tổ 18, Thôn 6 | M29: Thôn 6 | N29: Phường Cam Ly - Đà Lạt | O29: Lâm Đồng | Q29: Thôn 6 | V29: Lâm Đồng | Z29: 68214000834 | AC29: Cil | AD29: Không | AF29: 0 | AG29: 0 | AH29: 0 | AO29: 392365434
A30: 25 | B30: 6A | C30: 2007774899 | E30: 25 | F30: Sohao Phương | G30: Thùy | H30: Sohao Phương Thùy | I30: 41937 | J30: Nữ | K30: 58314005412 | L30: Đa Blah | N30: Xã Lạc Dương | O30: Lâm Đồng | Z30: 58314005412 | AC30: Cơ-ho | AD30: Không | AF30: 0 | AG30: 0 | AH30: 0 | AO30: 347061008
A31: 26 | B31: 6A | C31: 2007281828 | E31: 26 | F31: Liêng Jrang Ru | G31: Tơ | H31: Liêng Jrang Ru Tơ | I31: 41710 | J31: Nữ | K31: 68314011540 | L31: Thôn 4 | N31: Xã Lạc Dương | O31: Lâm Đồng | U31: Xã Lạc Dương | V31: Lâm Đồng | Z31: 68314011540 | AC31: Cil | AD31: Không | AF31: 0 | AG31: 0 | AH31: 0 | AO31: 392312023
A32: 27 | B32: 6A | C32: 2007398127 | E32: 27 | F32: Bùi Thị Huyền | G32: Trâm | H32: Bùi Thị Huyền Trâm | I32: 41652 | J32: Nữ | K32: 68314012856 | L32: Thôn Đưng K'Si | N32: Xã Lạc Dương | O32: Lâm Đồng | Z32: 68314012856 | AC32: Mường | AD32: Không | AF32: 0 | AG32: 0 | AH32: 0
A33: 28 | B33: 6A | C33: 2007290534 | E33: 28 | F33: Liêng Jrang Lệ | G33: Trinh | H33: Liêng Jrang Lệ Trinh | I33: 41809 | J33: Nữ | K33: 68314005705 | L33: Thôn 2 | N33: Xã Lạc Dương | O33: Lâm Đồng | Z33: 68314005705 | AC33: Cil | AD33: Không | AF33: 0 | AG33: 0 | AH33: 0 | AO33: 335906979
A34: 29 | B34: 6B | C34: 2005925205 | E34: 1 | F34: Trương Văn | G34: An | H34: Trương Văn An | I34: 41811 | J34: Nam | K34: 68214001956 | L34: Thôn 2 | M34: Thôn K'Nớ 2 | N34: Xã Đam Rông 4 | O34: Lâm Đồng | Q34: Thôn K'Nớ 2 | U34: Xã Đam Rông 4 | V34: Lâm Đồng | Z34: 68214001956 | AC34: Mường | AD34: Không | AF34: 0 | AG34: 0 | AH34: 0 | AO34: 968926721
A35: 30 | B35: 6B | C35: 2007291610 | E35: 2 | F35: Kră Jăn Ngọc | G35: Ánh | H35: Kră Jăn Ngọc Ánh | I35: 41945 | J35: Nữ | K35: 68314009847 | L35: Thôn 2 | N35: Xã Lạc Dương | O35: Lâm Đồng | Z35: 68314009847 | AC35: Cil | AD35: Không | AF35: 0 | AG35: 0 | AH35: 0 | AO35: 395629255
A36: 31 | B36: 6B | C36: 2005985972 | E36: 3 | F36: Liêng Hót | G36: Dêbôra | H36: Liêng Hót Dêbôra | I36: 41722 | J36: Nữ | K36: 68314002568 | L36: Thôn Đạ Nghịt 1 | N36: Phường Lang Biang - Đà Lạt | O36: Lâm Đồng | Z36: 68314002568 | AC36: Cil | AD36: Không | AF36: 0 | AG36: 0 | AH36: 0
A37: 32 | B37: 6B | C37: 2005927229 | E37: 4 | F37: Bon Niêng K' | G37: Gưm | H37: Bon Niêng K' Gưm | I37: 41912 | J37: Nữ | K37: 68314007649 | L37: Thôn 2 | M37: Thôn K'Nớ 2 | N37: Xã Đam Rông 4 | O37: Lâm Đồng | Q37: Thôn K'Nớ 2 | U37: Xã Đam Rông 4 | V37: Lâm Đồng | Z37: 68314007649 | AC37: Cơ-ho | AD37: Không | AF37: 0 | AG37: 0 | AH37: 0 | AO37: 948376973
A38: 33 | B38: 6B | C38: 2006153308 | E38: 5 | F38: Đà Cắt K' Na | G38: Hi | H38: Đà Cắt K' Na Hi | I38: 41763 | J38: Nữ | K38: 68314003096 | L38: Păng Tiêng 1 | N38: Phường Lang Biang - Đà Lạt | O38: Lâm Đồng | Z38: 68314003096 | AC38: Cơ-ho | AD38: Không | AF38: 0 | AG38: 0 | AH38: 0
A39: 34 | B39: 6B | C39: 2006027380 | E39: 6 | F39: Chu Nhật | G39: Huy | H39: Chu Nhật Huy | I39: 41978 | J39: Nam | K39: 68214005815 | L39: Thôn Lán Tranh | M39: Thôn Lán Tranh | N39: Xã Đam Rông 4 | O39: Lâm Đồng | Q39: Thôn Lán Tranh | U39: Xã Đam Rông 4 | V39: Lâm Đồng | Z39: 68214005815 | AC39: Tày | AD39: Không | AF39: 0 | AG39: 0 | AH39: 0 | AO39: 369493081
A40: 35 | B40: 6B | C40: 2009200496 | E40: 7 | F40: Lơ Mu | G40: Julia | H40: Lơ Mu Julia | I40: 41894 | J40: Nữ | K40: 68314001865 | L40: TDP Đăng Gia Det B | M40: Tổ dân phố Đăng Gia Dềt B | N40: Phường Lang Biang - Đà Lạt | O40: Lâm Đồng | Q40: Tổ dân phố Đăng Gia Dềt B | U40: Phường Cam Ly - Đà Lạt | V40: Lâm Đồng | Z40: 68314001865 | AC40: Cơ-ho | AD40: Không | AF40: 0 | AG40: 0 | AH40: 0 | AO40: 362157578
A41: 36 | B41: 6B | C41: 2005930679 | E41: 8 | F41: Cil Múp Ja | G41: Kốp | H41: Cil Múp Ja Kốp | I41: 41948 | J41: Nam | K41: 68214003691 | L41: Thôn 1 | M41: Thôn K'Nớ 1 | N41: Xã Đam Rông 4 | O41: Lâm Đồng | Q41: Thôn K'Nớ 1 | U41: Xã Đam Rông 4 | V41: Lâm Đồng | Z41: 68214003691 | AC41: Cơ-ho | AD41: Không | AF41: 0 | AG41: 0 | AH41: 0 | AO41: 344348515
A42: 37 | B42: 6B | C42: 2007291628 | E42: 9 | F42: Lơ Mu Shay | G42: La | H42: Lơ Mu Shay La | I42: 41920 | J42: Nữ | K42: 68314005592 | L42: Thôn 3 | N42: Xã Lạc Dương | O42: Lâm Đồng | Z42: 68314005592 | AC42: Cil | AD42: Không | AF42: 0 | AG42: 0 | AH42: 0 | AO42: 352972051
...

Sheet DS HS không ăn
F1: =COUNTIF(B5:B629,"?") -> 0 | J1: Tháng 02 / 2026 | DD1: Số lượng cắt phần ăn | DH1: =MAX($CN$2:$CY$2)*$F$3-DD3 -> 19843 | DI1: =MAX($CN$2:$CY$2)*$F$3-DE3 -> 19851 | DJ1: =MAX($CN$2:$CY$2)*$F$3-DF3 -> 19861
J2: Ngày | K2: 46054 | L2: 46054 | M2: 46054 | N2: 2 | O2: 2 | P2: 2 | Q2: 3 | R2: 3 | S2: 3 | T2: 4 | U2: 4 | V2: 4 | W2: 5 | X2: 5 | Y2: 5 | Z2: 6 | AA2: 6 | AB2: 6 | AC2: 7 | AD2: 7 | AE2: 7 | AF2: 8 | AG2: 8 | AH2: 8 | AI2: 9 | AJ2: 9 | AK2: 9 | AL2: 10 | AM2: 10 | AN2: 10 | AO2: 11 | AP2: 11 | AQ2: 11 | AR2: 12 | AS2: 12 | AT2: 12 | AU2: 13 | AV2: 13 | AW2: 13 | AX2: 14 | AY2: 14 | AZ2: 14 | BA2: 15 | BB2: 15 | BC2: 15 | BD2: 16 | BE2: 16 | BF2: 16 | BG2: 17 | BH2: 17 | BI2: 17 | BJ2: 18 | BK2: 18 | BL2: 18 | BM2: 19 | BN2: 19 | BO2: 19 | BP2: 20 | BQ2: 20 | BR2: 20 | BS2: 21 | BT2: 21 | BU2: 21 | BV2: 22 | BW2: 22 | BX2: 22 | BY2: 23 | BZ2: 23 | CA2: 23 | CB2: 24 | CC2: 24 | CD2: 24 | CE2: 25 | CF2: 25 | CG2: 25 | CH2: 26 | CI2: 26 | CJ2: 26 | CK2: 27 | CL2: 27 | CM2: 27 | CN2: 28 | CO2: 28 | CP2: 28 | CQ2: 29 | CR2: 29 | CS2: 29 | CT2: 30 | CU2: 30 | CV2: 30 | CW2: 31 | CX2: 31 | CY2: 31 | CZ2: 46054 | DA2: 46054 | DB2: 46054 | DE2: =DE3+DF3 -> 154 | DH2: Số buổi ăn | DI2: =DI3+DJ3 -> 39774
A3: =COUNTA(A5:A649) -> 643 | B3: =COUNTIF(B5:B629,"?") -> 0 | C3: =COUNTA(C5:C649) -> 643 | D3: =COUNTA(D5:D629) -> 0 | E3: =COUNTA(E5:E629) -> 151 | F3: =COUNTA(F5:F649) -> 643 | J3: Thứ | K3: CN | L3: CN | M3: CN | N3: Hai | Q3: Ba | T3: Tư | W3: Năm | Z3: Sáu | AC3: Bảy | AD3: Bảy | AE3: Bảy | AF3: CN | AG3: CN | AH3: CN | AI3: Hai | AL3: Ba | AO3: Tư | AR3: Năm | AU3: Sáu | AX3: Bảy | AY3: Bảy | AZ3: Bảy | BA3: CN | BB3: CN | BC3: CN | BD3: Hai | BG3: Ba | BJ3: Tư | BM3: Năm | BP3: Sáu | BS3: Bảy | BT3: Bảy | BU3: Bảy | BV3: CN | BW3: CN | BX3: CN | BY3: Hai | CB3: Ba | CE3: Tư | CH3: Năm | CK3: Sáu | CN3: Bảy | CO3: Bảy | CP3: Bảy | CZ3: CN | DA3: CN | DB3: CN | DD3: =SUM(DD5:DD649) -> 90 | DE3: =SUM(DE5:DE649) -> 82 | DF3: =SUM(DF5:DF649) -> 72 | DH3: =SUM(DH5:DH649) -> 19874 | DI3: =SUM(DI5:DI649) -> 19882 | DJ3: =SUM(DJ5:DJ649) -> 19892
A4: STT | B4: KT lớp | E4: STT | G4: Mã học sinh | H4: Mã MOET | I4: Số định danh | J4: Họ và tên | K4: Sáng | L4: Trưa | M4: Chiều | N4: Sáng | O4: Trưa | P4: Chiều | Q4: Sáng | R4: Trưa | S4: Chiều | T4: Sáng | U4: Trưa | V4: Chiều | W4: Sáng | X4: Trưa | Y4: Chiều | Z4: Sáng | AA4: Trưa | AB4: Chiều | AC4: Sáng | AD4: Trưa | AE4: Chiều | AF4: Sáng | AG4: Trưa | AH4: Chiều | AI4: Sáng | AJ4: Trưa | AK4: Chiều | AL4: Sáng | AM4: Trưa | AN4: Chiều | AO4: Sáng | AP4: Trưa | AQ4: Chiều | AR4: Sáng | AS4: Trưa | AT4: Chiều | AU4: Sáng | AV4: Trưa | AW4: Chiều | AX4: Sáng | AY4: Trưa | AZ4: Chiều | BA4: Sáng | BB4: Trưa | BC4: Chiều | BD4: Sáng | BE4: Trưa | BF4: Chiều | BG4: Sáng | BH4: Trưa | BI4: Chiều | BJ4: Sáng | BK4: Trưa | BL4: Chiều | BM4: Sáng | BN4: Trưa | BO4: Chiều | BP4: Sáng | BQ4: Trưa | BR4: Chiều | BS4: Sáng | BT4: Trưa | BU4: Chiều | BV4: Sáng | BW4: Trưa | BX4: Chiều | BY4: Sáng | BZ4: Trưa | CA4: Chiều | CB4: Sáng | CC4: Trưa | CD4: Chiều | CE4: Sáng | CF4: Trưa | CG4: Chiều | CH4: Sáng | CI4: Trưa | CJ4: Chiều | CK4: Sáng | CL4: Trưa | CM4: Chiều | CN4: Sáng | CO4: Trưa | CP4: Chiều | CZ4: Sáng | DA4: Trưa | DB4: Chiều | DD4: Sáng | DE4: Trưa | DF4: Chiều | DH4: Sáng | DI4: Trưa | DJ4: Chiều
A5: 1 | B5: =IF(C5<>F5,"?","") | C5: 6A | E5: 1 | F5: 6A | G5: 2005929926 | J5: Bon Niêng K' A Ngọc Bé | DD5: =COUNTA(CW5,CQ5,CN5,CK5,CH5,CB5,CE5,BY5,BV5,BS5,BP5,BM5,BJ5,BG5,BD5,BA5,AX5,AU5,AR5,AO5,AL5,AI5,AF5,AC5,Z5,W5,T5,Q5,N5,K5,CT5) -> 0 | DE5: =COUNTA(CX5,CR5,CO5,CL5,CI5,CC5,CF5,BZ5,BW5,BT5,BQ5,BN5,BK5,BH5,BE5,BB5,AY5,AV5,AS5,AP5,AM5,AJ5,AG5,AD5,AA5,X5,U5,R5,O5,L5,CU5) -> 0 | DF5: =COUNTA(CY5,CS5,CP5,CM5,CJ5,CD5,CG5,CA5,BX5,BU5,BR5,BO5,BL5,BI5,BF5,BC5,AZ5,AW5,AT5,AQ5,AN5,AK5,AH5,AE5,AB5,Y5,V5,S5,P5,M5,CV5) -> 0 | DH5: =MAX($CN$2:$CY$2)-DD5 -> 31 | DI5: =MAX($CN$2:$CY$2)-DE5 -> 31 | DJ5: =MAX($CN$2:$CY$2)-DF5 -> 31
